Workbook

Sheet Sheet1
A1: Name | B1: Job Name | C1: Address | D1: City | E1: State | F1: Zip | G1: Drawing Name | H1: Basin Size | I1: Overall Height | J1: Grate Types | K1: Grate Style | L1: Outlet 1 | M1: Outlet Type 1 | N1: Degrees 1 | O1: Invert Height 1 | P1: Outlet 2 | Q1: Outlet Type 2 | R1: Degrees 2 | S1: Invert Height 2 | T1: Outlet 3 | U1: Outlet Type 3 | V1: Degrees 3 | W1: Invert Height 3 | X1: Outlet 4 | Y1: Outlet Type 4 | Z1: Degrees 4 | AA1: Invert Height 4
A2: PRINSCO | B2: SAMPLE JOBSITE | G2: =IF(Sheet2!A2="","",Sheet2!A2) -> YD1 | H2: =IF(Sheet2!O2="","",LEFT(Sheet2!O2, FIND(" ", Sheet2!O2)-1)) -> 12" | I2: =IF(Sheet2!S2<19,ROUND(Sheet2!I2,2)&"'",IF(Sheet2!S2<25,ROUND(Sheet2!J2,2)&"'",IF(Sheet2!S2<31,ROUND(Sheet2!K2,2)&"'",IF(Sheet2!S2<37,ROUND(Sheet2!L2,2)&"'","")))) -> 3.17' | J2: Round w Frame | K2: H10 | L2: =IF(Sheet2!D2="","",Sheet2!D2&"''") -> 4'' | M2: PRINSCO HUB | N2: 0° | O2: =IF(Sheet2!H2="","",ROUND(Sheet2!H2,2)&"'") -> 2.67' | P2: =IF(Sheet2!E2="","",Sheet2!E2&"''") | T2: =IF(Sheet2!F2="","",Sheet2!F2&"''") | X2: =IF(Sheet2!G2="","",Sheet2!G2&"''")
G3: =IF(Sheet2!A3="","",Sheet2!A3) -> YD2 | H3: =IF(Sheet2!O3="","",LEFT(Sheet2!O3, FIND(" ", Sheet2!O3)-1)) -> 12" | I3: =IF(Sheet2!S3<19,ROUND(Sheet2!I3,2)&"'",IF(Sheet2!S3<25,ROUND(Sheet2!J3,2)&"'",IF(Sheet2!S3<31,ROUND(Sheet2!K3,2)&"'",IF(Sheet2!S3<37,ROUND(Sheet2!L3,2)&"'","")))) -> 3.52' | J3: Round w Frame | K3: H10 | L3: =IF(Sheet2!D3="","",Sheet2!D3&"''") -> 15'' | M3: PRINSCO HUB | N3: 0° | O3: =IF(Sheet2!H3="","",ROUND(Sheet2!H3,2)&"'") -> 3.02' | P3: =IF(Sheet2!E3="","",Sheet2!E3&"''") -> 12'' | Q3: PRINSCO HUB | R3: 155° | S3: 2.67' | T3: =IF(Sheet2!F3="","",Sheet2!F3&"''") | X3: =IF(Sheet2!G3="","",Sheet2!G3&"''")
G4: =IF(Sheet2!A4="","",Sheet2!A4) -> YD4 | H4: =IF(Sheet2!O4="","",LEFT(Sheet2!O4, FIND(" ", Sheet2!O4)-1)) -> 15" | I4: =IF(Sheet2!S4<19,ROUND(Sheet2!I4,2)&"'",IF(Sheet2!S4<25,ROUND(Sheet2!J4,2)&"'",IF(Sheet2!S4<31,ROUND(Sheet2!K4,2)&"'",IF(Sheet2!S4<37,ROUND(Sheet2!L4,2)&"'","")))) -> 3.72' | J4: Round w Frame | K4: Solid | L4: =IF(Sheet2!D4="","",Sheet2!D4&"''") -> 8'' | M4: PRINSCO HUB | N4: 0° | O4: =IF(Sheet2!H4="","",ROUND(Sheet2!H4,2)&"'") -> 3.22' | P4: =IF(Sheet2!E4="","",Sheet2!E4&"''") -> 8'' | Q4: PRINSCO HUB | R4: 175° | S4: 3.15' | T4: =IF(Sheet2!F4="","",Sheet2!F4&"''") -> 6'' | U4: PRINSCO HUB | V4: 90° | W4: 2.26' | X4: =IF(Sheet2!G4="","",Sheet2!G4&"''")
G5: =IF(Sheet2!A5="","",Sheet2!A5) -> YD3 | H5: =IF(Sheet2!O5="","",LEFT(Sheet2!O5, FIND(" ", Sheet2!O5)-1)) -> 12" | I5: =IF(Sheet2!S5<19,ROUND(Sheet2!I5,2)&"'",IF(Sheet2!S5<25,ROUND(Sheet2!J5,2)&"'",IF(Sheet2!S5<31,ROUND(Sheet2!K5,2)&"'",IF(Sheet2!S5<37,ROUND(Sheet2!L5,2)&"'","")))) -> 5' | J5: Round w Frame | K5: H10 | L5: =IF(Sheet2!D5="","",Sheet2!D5&"''") -> 18'' | M5: PRINSCO HUB | N5: 0° | O5: =IF(Sheet2!H5="","",ROUND(Sheet2!H5,2)&"'") -> 4.5' | P5: =IF(Sheet2!E5="","",Sheet2!E5&"''") | T5: =IF(Sheet2!F5="","",Sheet2!F5&"''") | X5: =IF(Sheet2!G5="","",Sheet2!G5&"''")
G6: =IF(Sheet2!A6="","",Sheet2!A6) -> YD6 | H6: =IF(Sheet2!O6="","",LEFT(Sheet2!O6, FIND(" ", Sheet2!O6)-1)) -> 24" | I6: =IF(Sheet2!S6<19,ROUND(Sheet2!I6,2)&"'",IF(Sheet2!S6<25,ROUND(Sheet2!J6,2)&"'",IF(Sheet2!S6<31,ROUND(Sheet2!K6,2)&"'",IF(Sheet2!S6<37,ROUND(Sheet2!L6,2)&"'","")))) -> 4.28' | J6: Domed w Frame | K6: H10 | L6: =IF(Sheet2!D6="","",Sheet2!D6&"''") -> 15'' | M6: PRINSCO HUB | N6: 0° | O6: =IF(Sheet2!H6="","",ROUND(Sheet2!H6,2)&"'") -> 3.61' | P6: =IF(Sheet2!E6="","",Sheet2!E6&"''") -> 8'' | Q6: PRINSCO HUB | R6: 145° | S6: 3.45' | T6: =IF(Sheet2!F6="","",Sheet2!F6&"''") | X6: =IF(Sheet2!G6="","",Sheet2!G6&"''")
G7: =IF(Sheet2!A7="","",Sheet2!A7) -> YD7 | H7: =IF(Sheet2!O7="","",LEFT(Sheet2!O7, FIND(" ", Sheet2!O7)-1)) -> 30" | I7: =IF(Sheet2!S7<19,ROUND(Sheet2!I7,2)&"'",IF(Sheet2!S7<25,ROUND(Sheet2!J7,2)&"'",IF(Sheet2!S7<31,ROUND(Sheet2!K7,2)&"'",IF(Sheet2!S7<37,ROUND(Sheet2!L7,2)&"'","")))) -> 5.12' | J7: Round w Frame | K7: H25 | L7: =IF(Sheet2!D7="","",Sheet2!D7&"''") -> 18'' | M7: PRINSCO HUB | N7: 0° | O7: =IF(Sheet2!H7="","",ROUND(Sheet2!H7,2)&"'") -> 4.29' | P7: =IF(Sheet2!E7="","",Sheet2!E7&"''") | T7: =IF(Sheet2!F7="","",Sheet2!F7&"''") | X7: =IF(Sheet2!G7="","",Sheet2!G7&"''")
G8: =IF(Sheet2!A8="","",Sheet2!A8) | H8: =IF(Sheet2!O8="","",LEFT(Sheet2!O8, FIND(" ", Sheet2!O8)-1)) | I8: =IF(Sheet2!S8<19,ROUND(Sheet2!I8,2)&"'",IF(Sheet2!S8<25,ROUND(Sheet2!J8,2)&"'",IF(Sheet2!S8<31,ROUND(Sheet2!K8,2)&"'",IF(Sheet2!S8<37,ROUND(Sheet2!L8,2)&"'","")))) | L8: =IF(Sheet2!D8="","",Sheet2!D8&"''") | O8: =IF(Sheet2!H8="","",ROUND(Sheet2!H8,2)&"'") | P8: =IF(Sheet2!E8="","",Sheet2!E8&"''") | T8: =IF(Sheet2!F8="","",Sheet2!F8&"''") | X8: =IF(Sheet2!G8="","",Sheet2!G8&"''")
G9: =IF(Sheet2!A9="","",Sheet2!A9) | H9: =IF(Sheet2!O9="","",LEFT(Sheet2!O9, FIND(" ", Sheet2!O9)-1)) | I9: =IF(Sheet2!S9<19,ROUND(Sheet2!I9,2)&"'",IF(Sheet2!S9<25,ROUND(Sheet2!J9,2)&"'",IF(Sheet2!S9<31,ROUND(Sheet2!K9,2)&"'",IF(Sheet2!S9<37,ROUND(Sheet2!L9,2)&"'","")))) | L9: =IF(Sheet2!D9="","",Sheet2!D9&"''") | O9: =IF(Sheet2!H9="","",ROUND(Sheet2!H9,2)&"'") | P9: =IF(Sheet2!E9="","",Sheet2!E9&"''") | T9: =IF(Sheet2!F9="","",Sheet2!F9&"''") | X9: =IF(Sheet2!G9="","",Sheet2!G9&"''")
G10: =IF(Sheet2!A10="","",Sheet2!A10) | H10: =IF(Sheet2!O10="","",LEFT(Sheet2!O10, FIND(" ", Sheet2!O10)-1)) | I10: =IF(Sheet2!S10<19,ROUND(Sheet2!I10,2)&"'",IF(Sheet2!S10<25,ROUND(Sheet2!J10,2)&"'",IF(Sheet2!S10<31,ROUND(Sheet2!K10,2)&"'",IF(Sheet2!S10<37,ROUND(Sheet2!L10,2)&"'","")))) | L10: =IF(Sheet2!D10="","",Sheet2!D10&"''") | O10: =IF(Sheet2!H10="","",ROUND(Sheet2!H10,2)&"'") | P10: =IF(Sheet2!E10="","",Sheet2!E10&"''") | T10: =IF(Sheet2!F10="","",Sheet2!F10&"''") | X10: =IF(Sheet2!G10="","",Sheet2!G10&"''")
G11: =IF(Sheet2!A11="","",Sheet2!A11) | H11: =IF(Sheet2!O11="","",LEFT(Sheet2!O11, FIND(" ", Sheet2!O11)-1)) | I11: =IF(Sheet2!S11<19,ROUND(Sheet2!I11,2)&"'",IF(Sheet2!S11<25,ROUND(Sheet2!J11,2)&"'",IF(Sheet2!S11<31,ROUND(Sheet2!K11,2)&"'",IF(Sheet2!S11<37,ROUND(Sheet2!L11,2)&"'","")))) | L11: =IF(Sheet2!D11="","",Sheet2!D11&"''") | O11: =IF(Sheet2!H11="","",ROUND(Sheet2!H11,2)&"'") | P11: =IF(Sheet2!E11="","",Sheet2!E11&"''") | T11: =IF(Sheet2!F11="","",Sheet2!F11&"''") | X11: =IF(Sheet2!G11="","",Sheet2!G11&"''")
G12: =IF(Sheet2!A12="","",Sheet2!A12) | H12: =IF(Sheet2!O12="","",LEFT(Sheet2!O12, FIND(" ", Sheet2!O12)-1)) | I12: =IF(Sheet2!S12<19,ROUND(Sheet2!I12,2)&"'",IF(Sheet2!S12<25,ROUND(Sheet2!J12,2)&"'",IF(Sheet2!S12<31,ROUND(Sheet2!K12,2)&"'",IF(Sheet2!S12<37,ROUND(Sheet2!L12,2)&"'","")))) | L12: =IF(Sheet2!D12="","",Sheet2!D12&"''") | O12: =IF(Sheet2!H12="","",ROUND(Sheet2!H12,2)&"'") | P12: =IF(Sheet2!E12="","",Sheet2!E12&"''") | T12: =IF(Sheet2!F12="","",Sheet2!F12&"''") | X12: =IF(Sheet2!G12="","",Sheet2!G12&"''")
G13: =IF(Sheet2!A13="","",Sheet2!A13) | H13: =IF(Sheet2!O13="","",LEFT(Sheet2!O13, FIND(" ", Sheet2!O13)-1)) | I13: =IF(Sheet2!S13<19,ROUND(Sheet2!I13,2)&"'",IF(Sheet2!S13<25,ROUND(Sheet2!J13,2)&"'",IF(Sheet2!S13<31,ROUND(Sheet2!K13,2)&"'",IF(Sheet2!S13<37,ROUND(Sheet2!L13,2)&"'","")))) | L13: =IF(Sheet2!D13="","",Sheet2!D13&"''") | O13: =IF(Sheet2!H13="","",ROUND(Sheet2!H13,2)&"'") | P13: =IF(Sheet2!E13="","",Sheet2!E13&"''") | T13: =IF(Sheet2!F13="","",Sheet2!F13&"''") | X13: =IF(Sheet2!G13="","",Sheet2!G13&"''")
G14: =IF(Sheet2!A14="","",Sheet2!A14) | H14: =IF(Sheet2!O14="","",LEFT(Sheet2!O14, FIND(" ", Sheet2!O14)-1)) | I14: =IF(Sheet2!S14<19,ROUND(Sheet2!I14,2)&"'",IF(Sheet2!S14<25,ROUND(Sheet2!J14,2)&"'",IF(Sheet2!S14<31,ROUND(Sheet2!K14,2)&"'",IF(Sheet2!S14<37,ROUND(Sheet2!L14,2)&"'","")))) | L14: =IF(Sheet2!D14="","",Sheet2!D14&"''") | O14: =IF(Sheet2!H14="","",ROUND(Sheet2!H14,2)&"'") | P14: =IF(Sheet2!E14="","",Sheet2!E14&"''") | T14: =IF(Sheet2!F14="","",Sheet2!F14&"''") | X14: =IF(Sheet2!G14="","",Sheet2!G14&"''")
G15: =IF(Sheet2!A15="","",Sheet2!A15) | H15: =IF(Sheet2!O15="","",LEFT(Sheet2!O15, FIND(" ", Sheet2!O15)-1)) | I15: =IF(Sheet2!S15<19,ROUND(Sheet2!I15,2)&"'",IF(Sheet2!S15<25,ROUND(Sheet2!J15,2)&"'",IF(Sheet2!S15<31,ROUND(Sheet2!K15,2)&"'",IF(Sheet2!S15<37,ROUND(Sheet2!L15,2)&"'","")))) | L15: =IF(Sheet2!D15="","",Sheet2!D15&"''") | O15: =IF(Sheet2!H15="","",ROUND(Sheet2!H15,2)&"'") | P15: =IF(Sheet2!E15="","",Sheet2!E15&"''") | T15: =IF(Sheet2!F15="","",Sheet2!F15&"''") | X15: =IF(Sheet2!G15="","",Sheet2!G15&"''")
G16: =IF(Sheet2!A16="","",Sheet2!A16) | H16: =IF(Sheet2!O16="","",LEFT(Sheet2!O16, FIND(" ", Sheet2!O16)-1)) | I16: =IF(Sheet2!S16<19,ROUND(Sheet2!I16,2)&"'",IF(Sheet2!S16<25,ROUND(Sheet2!J16,2)&"'",IF(Sheet2!S16<31,ROUND(Sheet2!K16,2)&"'",IF(Sheet2!S16<37,ROUND(Sheet2!L16,2)&"'","")))) | L16: =IF(Sheet2!D16="","",Sheet2!D16&"''") | O16: =IF(Sheet2!H16="","",ROUND(Sheet2!H16,2)&"'") | P16: =IF(Sheet2!E16="","",Sheet2!E16&"''") | T16: =IF(Sheet2!F16="","",Sheet2!F16&"''") | X16: =IF(Sheet2!G16="","",Sheet2!G16&"''")
G17: =IF(Sheet2!A17="","",Sheet2!A17) | H17: =IF(Sheet2!O17="","",LEFT(Sheet2!O17, FIND(" ", Sheet2!O17)-1)) | I17: =IF(Sheet2!S17<19,ROUND(Sheet2!I17,2)&"'",IF(Sheet2!S17<25,ROUND(Sheet2!J17,2)&"'",IF(Sheet2!S17<31,ROUND(Sheet2!K17,2)&"'",IF(Sheet2!S17<37,ROUND(Sheet2!L17,2)&"'","")))) | L17: =IF(Sheet2!D17="","",Sheet2!D17&"''") | O17: =IF(Sheet2!H17="","",ROUND(Sheet2!H17,2)&"'") | P17: =IF(Sheet2!E17="","",Sheet2!E17&"''") | T17: =IF(Sheet2!F17="","",Sheet2!F17&"''") | X17: =IF(Sheet2!G17="","",Sheet2!G17&"''")
G18: =IF(Sheet2!A18="","",Sheet2!A18) | H18: =IF(Sheet2!O18="","",LEFT(Sheet2!O18, FIND(" ", Sheet2!O18)-1)) | I18: =IF(Sheet2!S18<19,ROUND(Sheet2!I18,2)&"'",IF(Sheet2!S18<25,ROUND(Sheet2!J18,2)&"'",IF(Sheet2!S18<31,ROUND(Sheet2!K18,2)&"'",IF(Sheet2!S18<37,ROUND(Sheet2!L18,2)&"'","")))) | L18: =IF(Sheet2!D18="","",Sheet2!D18&"''") | O18: =IF(Sheet2!H18="","",ROUND(Sheet2!H18,2)&"'") | P18: =IF(Sheet2!E18="","",Sheet2!E18&"''") | T18: =IF(Sheet2!F18="","",Sheet2!F18&"''") | X18: =IF(Sheet2!G18="","",Sheet2!G18&"''")
G19: =IF(Sheet2!A19="","",Sheet2!A19) | H19: =IF(Sheet2!O19="","",LEFT(Sheet2!O19, FIND(" ", Sheet2!O19)-1)) | I19: =IF(Sheet2!S19<19,ROUND(Sheet2!I19,2)&"'",IF(Sheet2!S19<25,ROUND(Sheet2!J19,2)&"'",IF(Sheet2!S19<31,ROUND(Sheet2!K19,2)&"'",IF(Sheet2!S19<37,ROUND(Sheet2!L19,2)&"'","")))) | L19: =IF(Sheet2!D19="","",Sheet2!D19&"''") | O19: =IF(Sheet2!H19="","",ROUND(Sheet2!H19,2)&"'") | P19: =IF(Sheet2!E19="","",Sheet2!E19&"''") | T19: =IF(Sheet2!F19="","",Sheet2!F19&"''") | X19: =IF(Sheet2!G19="","",Sheet2!G19&"''")
... G93: =IF(Sheet2!A93="","",Sheet2!A93) | H93: =IF(Sheet2!O93="","",LEFT(Sheet2!O93, FIND(" ", Sheet2!O93)-1)) | I93: =IF(Sheet2!S93<19,ROUND(Sheet2!I93,2)&"'",IF(Sheet2!S93<25,ROUND(Sheet2!J93,2)&"'",IF(Sheet2!S93<31,ROUND(Sheet2!K93,2)&"'",IF(Sheet2!S93<37,ROUND(Sheet2!L93,2)&"'","")))) | L93: =IF(Sheet2!D93="","",Sheet2!D93&"''") | O93: =IF(Sheet2!H93="","",ROUND(Sheet2!H93,2)&"'") | P93: =IF(Sheet2!E93="","",Sheet2!E93&"''") | T93: =IF(Sheet2!F93="","",Sheet2!F93&"''") | X93: =IF(Sheet2!G93="","",Sheet2!G93&"''")
G94: =IF(Sheet2!A94="","",Sheet2!A94) | H94: =IF(Sheet2!O94="","",LEFT(Sheet2!O94, FIND(" ", Sheet2!O94)-1)) | I94: =IF(Sheet2!S94<19,ROUND(Sheet2!I94,2)&"'",IF(Sheet2!S94<25,ROUND(Sheet2!J94,2)&"'",IF(Sheet2!S94<31,ROUND(Sheet2!K94,2)&"'",IF(Sheet2!S94<37,ROUND(Sheet2!L94,2)&"'","")))) | L94: =IF(Sheet2!D94="","",Sheet2!D94&"''") | O94: =IF(Sheet2!H94="","",ROUND(Sheet2!H94,2)&"'") | P94: =IF(Sheet2!E94="","",Sheet2!E94&"''") | Q94: {=IF(P94="","",_xlfn.XLOOKUP(G94,[1]Sheet1!$G:$G,[1]Sheet1!$Q:$S))} | T94: =IF(Sheet2!F94="","",Sheet2!F94&"''") | U94: {=IF(T94="","",_xlfn.XLOOKUP(G94,[1]Sheet1!$G:$G,[1]Sheet1!$U:$W))} | X94: =IF(Sheet2!G94="","",Sheet2!G94&"''")
G95: =IF(Sheet2!A95="","",Sheet2!A95) | H95: =IF(Sheet2!O95="","",LEFT(Sheet2!O95, FIND(" ", Sheet2!O95)-1)) | I95: =IF(Sheet2!S95<19,ROUND(Sheet2!I95,2)&"'",IF(Sheet2!S95<25,ROUND(Sheet2!J95,2)&"'",IF(Sheet2!S95<31,ROUND(Sheet2!K95,2)&"'",IF(Sheet2!S95<37,ROUND(Sheet2!L95,2)&"'","")))) | L95: =IF(Sheet2!D95="","",Sheet2!D95&"''") | O95: =IF(Sheet2!H95="","",ROUND(Sheet2!H95,2)&"'") | P95: =IF(Sheet2!E95="","",Sheet2!E95&"''") | Q95: {=IF(P95="","",_xlfn.XLOOKUP(G95,[1]Sheet1!$G:$G,[1]Sheet1!$Q:$S))} | T95: =IF(Sheet2!F95="","",Sheet2!F95&"''") | U95: {=IF(T95="","",_xlfn.XLOOKUP(G95,[1]Sheet1!$G:$G,[1]Sheet1!$U:$W))} | X95: =IF(Sheet2!G95="","",Sheet2!G95&"''")
G96: =IF(Sheet2!A96="","",Sheet2!A96) | H96: =IF(Sheet2!O96="","",LEFT(Sheet2!O96, FIND(" ", Sheet2!O96)-1)) | I96: =IF(Sheet2!S96<19,ROUND(Sheet2!I96,2)&"'",IF(Sheet2!S96<25,ROUND(Sheet2!J96,2)&"'",IF(Sheet2!S96<31,ROUND(Sheet2!K96,2)&"'",IF(Sheet2!S96<37,ROUND(Sheet2!L96,2)&"'","")))) | L96: =IF(Sheet2!D96="","",Sheet2!D96&"''") | O96: =IF(Sheet2!H96="","",ROUND(Sheet2!H96,2)&"'") | P96: =IF(Sheet2!E96="","",Sheet2!E96&"''") | Q96: {=IF(P96="","",_xlfn.XLOOKUP(G96,[1]Sheet1!$G:$G,[1]Sheet1!$Q:$S))} | T96: =IF(Sheet2!F96="","",Sheet2!F96&"''") | U96: {=IF(T96="","",_xlfn.XLOOKUP(G96,[1]Sheet1!$G:$G,[1]Sheet1!$U:$W))} | X96: =IF(Sheet2!G96="","",Sheet2!G96&"''")
G97: =IF(Sheet2!A97="","",Sheet2!A97) | H97: =IF(Sheet2!O97="","",LEFT(Sheet2!O97, FIND(" ", Sheet2!O97)-1)) | I97: =IF(Sheet2!S97<19,ROUND(Sheet2!I97,2)&"'",IF(Sheet2!S97<25,ROUND(Sheet2!J97,2)&"'",IF(Sheet2!S97<31,ROUND(Sheet2!K97,2)&"'",IF(Sheet2!S97<37,ROUND(Sheet2!L97,2)&"'","")))) | L97: =IF(Sheet2!D97="","",Sheet2!D97&"''") | O97: =IF(Sheet2!H97="","",ROUND(Sheet2!H97,2)&"'") | P97: =IF(Sheet2!E97="","",Sheet2!E97&"''") | Q97: {=IF(P97="","",_xlfn.XLOOKUP(G97,[1]Sheet1!$G:$G,[1]Sheet1!$Q:$S))} | T97: =IF(Sheet2!F97="","",Sheet2!F97&"''") | U97: {=IF(T97="","",_xlfn.XLOOKUP(G97,[1]Sheet1!$G:$G,[1]Sheet1!$U:$W))} | X97: =IF(Sheet2!G97="","",Sheet2!G97&"''")
G98: =IF(Sheet2!A98="","",Sheet2!A98) | H98: =IF(Sheet2!O98="","",LEFT(Sheet2!O98, FIND(" ", Sheet2!O98)-1)) | I98: =IF(Sheet2!S98<19,ROUND(Sheet2!I98,2)&"'",IF(Sheet2!S98<25,ROUND(Sheet2!J98,2)&"'",IF(Sheet2!S98<31,ROUND(Sheet2!K98,2)&"'",IF(Sheet2!S98<37,ROUND(Sheet2!L98,2)&"'","")))) | L98: =IF(Sheet2!D98="","",Sheet2!D98&"''") | O98: =IF(Sheet2!H98="","",ROUND(Sheet2!H98,2)&"'") | P98: =IF(Sheet2!E98="","",Sheet2!E98&"''") | Q98: {=IF(P98="","",_xlfn.XLOOKUP(G98,[1]Sheet1!$G:$G,[1]Sheet1!$Q:$S))} | T98: =IF(Sheet2!F98="","",Sheet2!F98&"''") | U98: {=IF(T98="","",_xlfn.XLOOKUP(G98,[1]Sheet1!$G:$G,[1]Sheet1!$U:$W))} | X98: =IF(Sheet2!G98="","",Sheet2!G98&"''")
G99: =IF(Sheet2!A99="","",Sheet2!A99) | H99: =IF(Sheet2!O99="","",LEFT(Sheet2!O99, FIND(" ", Sheet2!O99)-1)) | I99: =IF(Sheet2!S99<19,ROUND(Sheet2!I99,2)&"'",IF(Sheet2!S99<25,ROUND(Sheet2!J99,2)&"'",IF(Sheet2!S99<31,ROUND(Sheet2!K99,2)&"'",IF(Sheet2!S99<37,ROUND(Sheet2!L99,2)&"'","")))) | L99: =IF(Sheet2!D99="","",Sheet2!D99&"''") | O99: =IF(Sheet2!H99="","",ROUND(Sheet2!H99,2)&"'") | P99: =IF(Sheet2!E99="","",Sheet2!E99&"''") | Q99: {=IF(P99="","",_xlfn.XLOOKUP(G99,[1]Sheet1!$G:$G,[1]Sheet1!$Q:$S))} | T99: =IF(Sheet2!F99="","",Sheet2!F99&"''") | U99: {=IF(T99="","",_xlfn.XLOOKUP(G99,[1]Sheet1!$G:$G,[1]Sheet1!$U:$W))} | X99: =IF(Sheet2!G99="","",Sheet2!G99&"''")
G100: =IF(Sheet2!A100="","",Sheet2!A100) | H100: =IF(Sheet2!O100="","",LEFT(Sheet2!O100, FIND(" ", Sheet2!O100)-1)) | I100: =IF(Sheet2!S100<19,ROUND(Sheet2!I100,2)&"'",IF(Sheet2!S100<25,ROUND(Sheet2!J100,2)&"'",IF(Sheet2!S100<31,ROUND(Sheet2!K100,2)&"'",IF(Sheet2!S100<37,ROUND(Sheet2!L100,2)&"'","")))) | L100: =IF(Sheet2!D100="","",Sheet2!D100&"''") | O100: =IF(Sheet2!H100="","",ROUND(Sheet2!H100,2)&"'") | P100: =IF(Sheet2!E100="","",Sheet2!E100&"''") | Q100: {=IF(P100="","",_xlfn.XLOOKUP(G100,[1]Sheet1!$G:$G,[1]Sheet1!$Q:$S))} | T100: =IF(Sheet2!F100="","",Sheet2!F100&"''") | U100: {=IF(T100="","",_xlfn.XLOOKUP(G100,[1]Sheet1!$G:$G,[1]Sheet1!$U:$W))} | X100: =IF(Sheet2!G100="","",Sheet2!G100&"''")
G101: =IF(Sheet2!A101="","",Sheet2!A101) | H101: =IF(Sheet2!O101="","",LEFT(Sheet2!O101, FIND(" ", Sheet2!O101)-1)) | I101: =IF(Sheet2!S101<19,ROUND(Sheet2!I101,2)&"'",IF(Sheet2!S101<25,ROUND(Sheet2!J101,2)&"'",IF(Sheet2!S101<31,ROUND(Sheet2!K101,2)&"'",IF(Sheet2!S101<37,ROUND(Sheet2!L101,2)&"'","")))) | L101: =IF(Sheet2!D101="","",Sheet2!D101&"''") | O101: =IF(Sheet2!H101="","",ROUND(Sheet2!H101,2)&"'") | P101: =IF(Sheet2!E101="","",Sheet2!E101&"''") | Q101: {=IF(P101="","",_xlfn.XLOOKUP(G101,[1]Sheet1!$G:$G,[1]Sheet1!$Q:$S))} | T101: =IF(Sheet2!F101="","",Sheet2!F101&"''") | U101: {=IF(T101="","",_xlfn.XLOOKUP(G101,[1]Sheet1!$G:$G,[1]Sheet1!$U:$W))} | X101: =IF(Sheet2!G101="","",Sheet2!G101&"''")
G102: =IF(Sheet2!A102="","",Sheet2!A102) | H102: =IF(Sheet2!O102="","",LEFT(Sheet2!O102, FIND(" ", Sheet2!O102)-1)) | I102: =IF(Sheet2!S102<19,ROUND(Sheet2!I102,2)&"'",IF(Sheet2!S102<25,ROUND(Sheet2!J102,2)&"'",IF(Sheet2!S102<31,ROUND(Sheet2!K102,2)&"'",IF(Sheet2!S102<37,ROUND(Sheet2!L102,2)&"'","")))) | L102: =IF(Sheet2!D102="","",Sheet2!D102&"''") | O102: =IF(Sheet2!H102="","",ROUND(Sheet2!H102,2)&"'") | P102: =IF(Sheet2!E102="","",Sheet2!E102&"''") | Q102: {=IF(P102="","",_xlfn.XLOOKUP(G102,[1]Sheet1!$G:$G,[1]Sheet1!$Q:$S))} | T102: =IF(Sheet2!F102="","",Sheet2!F102&"''") | U102: {=IF(T102="","",_xlfn.XLOOKUP(G102,[1]Sheet1!$G:$G,[1]Sheet1!$U:$W))} | X102: =IF(Sheet2!G102="","",Sheet2!G102&"''")
G103: =IF(Sheet2!A103="","",Sheet2!A103) | H103: =IF(Sheet2!O103="","",LEFT(Sheet2!O103, FIND(" ", Sheet2!O103)-1)) | I103: =IF(Sheet2!S103<19,ROUND(Sheet2!I103,2)&"'",IF(Sheet2!S103<25,ROUND(Sheet2!J103,2)&"'",IF(Sheet2!S103<31,ROUND(Sheet2!K103,2)&"'",IF(Sheet2!S103<37,ROUND(Sheet2!L103,2)&"'","")))) | L103: =IF(Sheet2!D103="","",Sheet2!D103&"''") | O103: =IF(Sheet2!H103="","",ROUND(Sheet2!H103,2)&"'") | P103: =IF(Sheet2!E103="","",Sheet2!E103&"''") | Q103: {=IF(P103="","",_xlfn.XLOOKUP(G103,[1]Sheet1!$G:$G,[1]Sheet1!$Q:$S))} | T103: =IF(Sheet2!F103="","",Sheet2!F103&"''") | U103: {=IF(T103="","",_xlfn.XLOOKUP(G103,[1]Sheet1!$G:$G,[1]Sheet1!$U:$W))} | X103: =IF(Sheet2!G103="","",Sheet2!G103&"''")
G104: =IF(Sheet2!A104="","",Sheet2!A104) | H104: =IF(Sheet2!O104="","",LEFT(Sheet2!O104, FIND(" ", Sheet2!O104)-1)) | I104: =IF(Sheet2!S104<19,ROUND(Sheet2!I104,2)&"'",IF(Sheet2!S104<25,ROUND(Sheet2!J104,2)&"'",IF(Sheet2!S104<31,ROUND(Sheet2!K104,2)&"'",IF(Sheet2!S104<37,ROUND(Sheet2!L104,2)&"'","")))) | L104: =IF(Sheet2!D104="","",Sheet2!D104&"''") | O104: =IF(Sheet2!H104="","",ROUND(Sheet2!H104,2)&"'") | P104: =IF(Sheet2!E104="","",Sheet2!E104&"''") | Q104: {=IF(P104="","",_xlfn.XLOOKUP(G104,[1]Sheet1!$G:$G,[1]Sheet1!$Q:$S))} | T104: =IF(Sheet2!F104="","",Sheet2!F104&"''") | U104: {=IF(T104="","",_xlfn.XLOOKUP(G104,[1]Sheet1!$G:$G,[1]Sheet1!$U:$W))} | X104: =IF(Sheet2!G104="","",Sheet2!G104&"''")
G105: =IF(Sheet2!A105="","",Sheet2!A105) | H105: =IF(Sheet2!O105="","",LEFT(Sheet2!O105, FIND(" ", Sheet2!O105)-1)) | I105: =IF(Sheet2!S105<19,ROUND(Sheet2!I105,2)&"'",IF(Sheet2!S105<25,ROUND(Sheet2!J105,2)&"'",IF(Sheet2!S105<31,ROUND(Sheet2!K105,2)&"'",IF(Sheet2!S105<37,ROUND(Sheet2!L105,2)&"'","")))) | L105: =IF(Sheet2!D105="","",Sheet2!D105&"''") | O105: =IF(Sheet2!H105="","",ROUND(Sheet2!H105,2)&"'") | P105: =IF(Sheet2!E105="","",Sheet2!E105&"''") | Q105: {=IF(P105="","",_xlfn.XLOOKUP(G105,[1]Sheet1!$G:$G,[1]Sheet1!$Q:$S))} | T105: =IF(Sheet2!F105="","",Sheet2!F105&"''") | U105: {=IF(T105="","",_xlfn.XLOOKUP(G105,[1]Sheet1!$G:$G,[1]Sheet1!$U:$W))} | X105: =IF(Sheet2!G105="","",Sheet2!G105&"''")
... G138: =IF(Sheet2!A138="","",Sheet2!A138) | H138: =IF(Sheet2!O138="","",LEFT(Sheet2!O138, FIND(" ", Sheet2!O138)-1)) | I138: =IF(Sheet2!S138<19,ROUND(Sheet2!I138,2)&"'",IF(Sheet2!S138<25,ROUND(Sheet2!J138,2)&"'",IF(Sheet2!S138<31,ROUND(Sheet2!K138,2)&"'",IF(Sheet2!S138<37,ROUND(Sheet2!L138,2)&"'","")))) | L138: =IF(Sheet2!D138="","",Sheet2!D138&"''") | O138: =IF(Sheet2!H138="","",ROUND(Sheet2!H138,2)&"'") | P138: =IF(Sheet2!E138="","",Sheet2!E138&"''") | Q138: {=IF(P138="","",_xlfn.XLOOKUP(G138,[1]Sheet1!$G:$G,[1]Sheet1!$Q:$S))} | T138: =IF(Sheet2!F138="","",Sheet2!F138&"''") | U138: {=IF(T138="","",_xlfn.XLOOKUP(G138,[1]Sheet1!$G:$G,[1]Sheet1!$U:$W))} | X138: =IF(Sheet2!G138="","",Sheet2!G138&"''")
G139: =IF(Sheet2!A139="","",Sheet2!A139) | H139: =IF(Sheet2!O139="","",LEFT(Sheet2!O139, FIND(" ", Sheet2!O139)-1)) | I139: =IF(Sheet2!S139<19,ROUND(Sheet2!I139,2)&"'",IF(Sheet2!S139<25,ROUND(Sheet2!J139,2)&"'",IF(Sheet2!S139<31,ROUND(Sheet2!K139,2)&"'",IF(Sheet2!S139<37,ROUND(Sheet2!L139,2)&"'","")))) | L139: =IF(Sheet2!D139="","",Sheet2!D139&"''") | O139: =IF(Sheet2!H139="","",ROUND(Sheet2!H139,2)&"'") | P139: =IF(Sheet2!E139="","",Sheet2!E139&"''") | Q139: {=IF(P139="","",_xlfn.XLOOKUP(G139,[1]Sheet1!$G:$G,[1]Sheet1!$Q:$S))} | T139: =IF(Sheet2!F139="","",Sheet2!F139&"""") | U139: {=IF(T139="","",_xlfn.XLOOKUP(G139,[1]Sheet1!$G:$G,[1]Sheet1!$U:$W))} | X139: =IF(Sheet2!G139="","",Sheet2!G139&"''")
G140: =IF(Sheet2!A140="","",Sheet2!A140) | H140: =IF(Sheet2!O140="","",LEFT(Sheet2!O140, FIND(" ", Sheet2!O140)-1)) | I140: =IF(Sheet2!S140<19,ROUND(Sheet2!I140,2)&"'",IF(Sheet2!S140<25,ROUND(Sheet2!J140,2)&"'",IF(Sheet2!S140<31,ROUND(Sheet2!K140,2)&"'",IF(Sheet2!S140<37,ROUND(Sheet2!L140,2)&"'","")))) | L140: =IF(Sheet2!D140="","",Sheet2!D140&"''") | O140: =IF(Sheet2!H140="","",ROUND(Sheet2!H140,2)&"'") | P140: =IF(Sheet2!E140="","",Sheet2!E140&"''") | Q140: {=IF(P140="","",_xlfn.XLOOKUP(G140,[1]Sheet1!$G:$G,[1]Sheet1!$Q:$S))} | T140: =IF(Sheet2!F140="","",Sheet2!F140&"""") | U140: {=IF(T140="","",_xlfn.XLOOKUP(G140,[1]Sheet1!$G:$G,[1]Sheet1!$U:$W))} | X140: =IF(Sheet2!G140="","",Sheet2!G140&"''")
G141: =IF(Sheet2!A141="","",Sheet2!A141) | H141: =IF(Sheet2!O141="","",LEFT(Sheet2!O141, FIND(" ", Sheet2!O141)-1)) | I141: =IF(Sheet2!S141<19,ROUND(Sheet2!I141,2)&"'",IF(Sheet2!S141<25,ROUND(Sheet2!J141,2)&"'",IF(Sheet2!S141<31,ROUND(Sheet2!K141,2)&"'",IF(Sheet2!S141<37,ROUND(Sheet2!L141,2)&"'","")))) | L141: =IF(Sheet2!D141="","",Sheet2!D141&"''") | O141: =IF(Sheet2!H141="","",ROUND(Sheet2!H141,2)&"'") | P141: =IF(Sheet2!E141="","",Sheet2!E141&"''") | Q141: {=IF(P141="","",_xlfn.XLOOKUP(G141,[1]Sheet1!$G:$G,[1]Sheet1!$Q:$S))} | T141: =IF(Sheet2!F141="","",Sheet2!F141&"""") | U141: {=IF(T141="","",_xlfn.XLOOKUP(G141,[1]Sheet1!$G:$G,[1]Sheet1!$U:$W))} | X141: =IF(Sheet2!G141="","",Sheet2!G141&"''")
G142: =IF(Sheet2!A142="","",Sheet2!A142) | H142: =IF(Sheet2!O142="","",LEFT(Sheet2!O142, FIND(" ", Sheet2!O142)-1)) | I142: =IF(Sheet2!S142<19,ROUND(Sheet2!I142,2)&"'",IF(Sheet2!S142<25,ROUND(Sheet2!J142,2)&"'",IF(Sheet2!S142<31,ROUND(Sheet2!K142,2)&"'",IF(Sheet2!S142<37,ROUND(Sheet2!L142,2)&"'","")))) | L142: =IF(Sheet2!D142="","",Sheet2!D142&"''") | O142: =IF(Sheet2!H142="","",ROUND(Sheet2!H142,2)&"'") | P142: =IF(Sheet2!E142="","",Sheet2!E142&"''") | Q142: {=IF(P142="","",_xlfn.XLOOKUP(G142,[1]Sheet1!$G:$G,[1]Sheet1!$Q:$S))} | T142: =IF(Sheet2!F142="","",Sheet2!F142&"""") | U142: {=IF(T142="","",_xlfn.XLOOKUP(G142,[1]Sheet1!$G:$G,[1]Sheet1!$U:$W))} | X142: =IF(Sheet2!G142="","",Sheet2!G142&"''")
G143: =IF(Sheet2!A143="","",Sheet2!A143) | H143: =IF(Sheet2!O143="","",LEFT(Sheet2!O143, FIND(" ", Sheet2!O143)-1)) | I143: =IF(Sheet2!S143<19,ROUND(Sheet2!I143,2)&"'",IF(Sheet2!S143<25,ROUND(Sheet2!J143,2)&"'",IF(Sheet2!S143<31,ROUND(Sheet2!K143,2)&"'",IF(Sheet2!S143<37,ROUND(Sheet2!L143,2)&"'","")))) | L143: =IF(Sheet2!D143="","",Sheet2!D143&"''") | O143: =IF(Sheet2!H143="","",ROUND(Sheet2!H143,2)&"'") | P143: =IF(Sheet2!E143="","",Sheet2!E143&"''") | Q143: {=IF(P143="","",_xlfn.XLOOKUP(G143,[1]Sheet1!$G:$G,[1]Sheet1!$Q:$S))} | T143: =IF(Sheet2!F143="","",Sheet2!F143&"""") | U143: {=IF(T143="","",_xlfn.XLOOKUP(G143,[1]Sheet1!$G:$G,[1]Sheet1!$U:$W))} | X143: =IF(Sheet2!G143="","",Sheet2!G143&"''")
G144: =IF(Sheet2!A144="","",Sheet2!A144) | H144: =IF(Sheet2!O144="","",LEFT(Sheet2!O144, FIND(" ", Sheet2!O144)-1)) | I144: =IF(Sheet2!S144<19,ROUND(Sheet2!I144,2)&"'",IF(Sheet2!S144<25,ROUND(Sheet2!J144,2)&"'",IF(Sheet2!S144<31,ROUND(Sheet2!K144,2)&"'",IF(Sheet2!S144<37,ROUND(Sheet2!L144,2)&"'","")))) | L144: =IF(Sheet2!D144="","",Sheet2!D144&"''") | O144: =IF(Sheet2!H144="","",ROUND(Sheet2!H144,2)&"'") | P144: =IF(Sheet2!E144="","",Sheet2!E144&"''") | Q144: {=IF(P144="","",_xlfn.XLOOKUP(G144,[1]Sheet1!$G:$G,[1]Sheet1!$Q:$S))} | T144: =IF(Sheet2!F144="","",Sheet2!F144&"""") | U144: {=IF(T144="","",_xlfn.XLOOKUP(G144,[1]Sheet1!$G:$G,[1]Sheet1!$U:$W))} | X144: =IF(Sheet2!G144="","",Sheet2!G144&"''")
G145: =IF(Sheet2!A145="","",Sheet2!A145) | H145: =IF(Sheet2!O145="","",LEFT(Sheet2!O145, FIND(" ", Sheet2!O145)-1)) | I145: =IF(Sheet2!S145<19,ROUND(Sheet2!I145,2)&"'",IF(Sheet2!S145<25,ROUND(Sheet2!J145,2)&"'",IF(Sheet2!S145<31,ROUND(Sheet2!K145,2)&"'",IF(Sheet2!S145<37,ROUND(Sheet2!L145,2)&"'","")))) | L145: =IF(Sheet2!D145="","",Sheet2!D145&"''") | O145: =IF(Sheet2!H145="","",ROUND(Sheet2!H145,2)&"'") | P145: =IF(Sheet2!E145="","",Sheet2!E145&"''") | Q145: {=IF(P145="","",_xlfn.XLOOKUP(G145,[1]Sheet1!$G:$G,[1]Sheet1!$Q:$S))} | T145: =IF(Sheet2!F145="","",Sheet2!F145&"""") | U145: {=IF(T145="","",_xlfn.XLOOKUP(G145,[1]Sheet1!$G:$G,[1]Sheet1!$U:$W))} | X145: =IF(Sheet2!G145="","",Sheet2!G145&"''")
...

Sheet Sheet2
A1: DN# | B1: TOG | C1: IE | D1: OUTLET D | E1: OUTLET D | F1: OUTLET D | G1: OUTLET D | H1: RIM-IE | I1: BASIN 8-18" | J1: BASIN 24" | K1: BASIN 30" | L1: BASIN 36" | M1: PRICE | N1: DRAWING NAME | O1: OUTLET DISCRIPTION | P1: Comment Notes | R1: PART NUMBER
A2: YD1 | B2: 1238.07 | C2: 1235.4 | D2: 4 | H2: =IF(C2="","",B2-C2) -> 2.67 | I2: =IF(H2="","",H2+0.5) -> 3.17 | J2: =IF(H2="","",H2+0.67) -> 3.34 | K2: =IF(H2="","",H2+0.83) -> 3.5 | L2: =IF(H2="","",H2+1.17) -> 3.84 | N2: =IF(A2="","",A2) -> YD1 | O2: =IF(R2="","",_xlfn.XLOOKUP(R2,[2]Sheet2!B:B,[2]Sheet2!C:C)) -> 12" Drain Basin W/ Slotted H10 Grate, 0'-5' | P2: =_xlfn.TEXTJOIN(", ", TRUE, IF(Y2<>"", Y2, ""), IF(Z2<>"", Z2, ""), IF(AA2<>"", AA2, ""),IF(AB2<>"",AB2,""), IF(AC2<>"", AC2, ""),IF(AD2<>"", AD2, ""),IF(AE2<>"", AE2, ""),IF(AF2<>"", AF2, ""),IF(AG2<>"", AG2, "")) -> 1 X 4" | R2: DB1205PS | S2: =IF(Sheet2!O2="","",--LEFT(Sheet2!O2,FIND("""",Sheet2!O2)-1)) -> 12 | T2: =IF(D2=4,21, IF(D2=6,27,IF(D2=8,29,IF(D2=10,34,IF(D2=12,42,IF(D2=15,64,IF(D2=18,124,IF(D2=24,267,IF(D2=30,416,IF(D2=36,520,"")))))))))) -> 21 | U2: =IF(E2=4,21, IF(E2=6,27,IF(E2=8,29,IF(E2=10,34,IF(E2=12,42,IF(E2=15,64,IF(E2=18,124,IF(E2=24,267,IF(E2=30,416,IF(E2=36,520,"")))))))))) | V2: =IF(F2=4,21, IF(F2=6,27,IF(F2=8,29,IF(F2=10,34,IF(F2=12,42,IF(F2=15,64,IF(F2=18,124,IF(F2=24,267,IF(F2=30,416,IF(F2=36,520,"")))))))))) | W2: =IF(G2=4,21, IF(G2=6,27,IF(G2=8,29,IF(G2=10,34,IF(G2=12,42,IF(G2=15,64,IF(G2=18,124,IF(G2=24,267,IF(G2=30,416,IF(G2=36,520,"")))))))))) | X2: =SUM(T2:W2) -> 21 | Y2: =IF(SUM(COUNTIF(D2:G2,4))>0,SUM(COUNTIF(D2:G2,4))&" X 4""","") -> 1 X 4" | Z2: =IF(SUM(COUNTIF(D2:G2,6))>0,SUM(COUNTIF(D2:G2,6))&" X 6""","") | AA2: =IF(SUM(COUNTIF(D2:G2,8))>0,SUM(COUNTIF(D2:G2,8))&" X 8""","") | AB2: =IF(SUM(COUNTIF(D2:G2,10))>0,SUM(COUNTIF(D2:G2,10))&" X 10""","") | AC2: =IF(SUM(COUNTIF(D2:G2,12))>0,SUM(COUNTIF(D2:G2,12))&" X 12""","") | AD2: =IF(SUM(COUNTIF(D2:G2,15))>0,SUM(COUNTIF(D2:G2,15))&" X 15""","") | AE2: =IF(SUM(COUNTIF(D2:G2,18))>0,SUM(COUNTIF(D2:G2,18))&" X 18""","") | AF2: =IF(SUM(COUNTIF(D2:G2,24))>0,SUM(COUNTIF(D2:G2,24))&" X 24""","") | AG2: =IF(SUM(COUNTIF(D2:G2,30))>0,SUM(COUNTIF(D2:G2,30))&" X 30""","")
A3: YD2 | B3: 1234.63 | C3: 1231.61 | D3: 15 | E3: 12 | H3: =IF(C3="","",B3-C3) -> 3.02 | I3: =IF(H3="","",H3+0.5) -> 3.52 | J3: =IF(H3="","",H3+0.67) -> 3.69 | K3: =IF(H3="","",H3+0.83) -> 3.85 | L3: =IF(H3="","",H3+1.17) -> 4.19 | N3: =IF(A3="","",A3) -> YD2 | O3: =IF(R3="","",_xlfn.XLOOKUP(R3,[2]Sheet2!B:B,[2]Sheet2!C:C)) -> 12" Drain Basin W/ Slotted H10 Grate, 0'-5' | P3: =_xlfn.TEXTJOIN(", ", TRUE, IF(Y3<>"", Y3, ""), IF(Z3<>"", Z3, ""), IF(AA3<>"", AA3, ""),IF(AB3<>"",AB3,""), IF(AC3<>"", AC3, ""),IF(AD3<>"", AD3, ""),IF(AE3<>"", AE3, ""),IF(AF3<>"", AF3, ""),IF(AG3<>"", AG3, "")) -> 1 X 12", 1 X 15" | R3: DB1205PS | S3: =IF(Sheet2!O3="","",--LEFT(Sheet2!O3,FIND("""",Sheet2!O3)-1)) -> 12 | T3: =IF(D3=4,21, IF(D3=6,27,IF(D3=8,29,IF(D3=10,34,IF(D3=12,42,IF(D3=15,64,IF(D3=18,124,IF(D3=24,267,IF(D3=30,416,IF(D3=36,520,"")))))))))) -> 64 | U3: =IF(E3=4,21, IF(E3=6,27,IF(E3=8,29,IF(E3=10,34,IF(E3=12,42,IF(E3=15,64,IF(E3=18,124,IF(E3=24,267,IF(E3=30,416,IF(E3=36,520,"")))))))))) -> 42 | V3: =IF(F3=4,21, IF(F3=6,27,IF(F3=8,29,IF(F3=10,34,IF(F3=12,42,IF(F3=15,64,IF(F3=18,124,IF(F3=24,267,IF(F3=30,416,IF(F3=36,520,"")))))))))) | W3: =IF(G3=4,21, IF(G3=6,27,IF(G3=8,29,IF(G3=10,34,IF(G3=12,42,IF(G3=15,64,IF(G3=18,124,IF(G3=24,267,IF(G3=30,416,IF(G3=36,520,"")))))))))) | X3: =SUM(T3:W3) -> 106 | Y3: =IF(SUM(COUNTIF(D3:G3,4))>0,SUM(COUNTIF(D3:G3,4))&" X 4""","") | Z3: =IF(SUM(COUNTIF(D3:G3,6))>0,SUM(COUNTIF(D3:G3,6))&" X 6""","") | AA3: =IF(SUM(COUNTIF(D3:G3,8))>0,SUM(COUNTIF(D3:G3,8))&" X 8""","") | AB3: =IF(SUM(COUNTIF(D3:G3,10))>0,SUM(COUNTIF(D3:G3,10))&" X 10""","") | AC3: =IF(SUM(COUNTIF(D3:G3,12))>0,SUM(COUNTIF(D3:G3,12))&" X 12""","") -> 1 X 12" | AD3: =IF(SUM(COUNTIF(D3:G3,15))>0,SUM(COUNTIF(D3:G3,15))&" X 15""","") -> 1 X 15" | AE3: =IF(SUM(COUNTIF(D3:G3,18))>0,SUM(COUNTIF(D3:G3,18))&" X 18""","") | AF3: =IF(SUM(COUNTIF(D3:G3,24))>0,SUM(COUNTIF(D3:G3,24))&" X 24""","") | AG3: =IF(SUM(COUNTIF(D3:G3,30))>0,SUM(COUNTIF(D3:G3,30))&" X 30""","")
A4: YD4 | B4: 1232.41 | C4: 1229.19 | D4: 8 | E4: 8 | F4: 6 | H4: =IF(C4="","",B4-C4) -> 3.22 | I4: =IF(H4="","",H4+0.5) -> 3.72 | J4: =IF(H4="","",H4+0.67) -> 3.89 | K4: =IF(H4="","",H4+0.83) -> 4.05 | L4: =IF(H4="","",H4+1.17) -> 4.39 | N4: =IF(A4="","",A4) -> YD4 | O4: =IF(R4="","",_xlfn.XLOOKUP(R4,[2]Sheet2!B:B,[2]Sheet2!C:C)) -> 15" Drain Basin W/H-25 Round Solid Cover/Frame, 5' - 10' | P4: =_xlfn.TEXTJOIN(", ", TRUE, IF(Y4<>"", Y4, ""), IF(Z4<>"", Z4, ""), IF(AA4<>"", AA4, ""),IF(AB4<>"",AB4,""), IF(AC4<>"", AC4, ""),IF(AD4<>"", AD4, ""),IF(AE4<>"", AE4, ""),IF(AF4<>"", AF4, ""),IF(AG4<>"", AG4, "")) -> 1 X 6", 2 X 8" | R4: DB1510SC | S4: =IF(Sheet2!O4="","",--LEFT(Sheet2!O4,FIND("""",Sheet2!O4)-1)) -> 15 | T4: =IF(D4=4,21, IF(D4=6,27,IF(D4=8,29,IF(D4=10,34,IF(D4=12,42,IF(D4=15,64,IF(D4=18,124,IF(D4=24,267,IF(D4=30,416,IF(D4=36,520,"")))))))))) -> 29 | U4: =IF(E4=4,21, IF(E4=6,27,IF(E4=8,29,IF(E4=10,34,IF(E4=12,42,IF(E4=15,64,IF(E4=18,124,IF(E4=24,267,IF(E4=30,416,IF(E4=36,520,"")))))))))) -> 29 | V4: =IF(F4=4,21, IF(F4=6,27,IF(F4=8,29,IF(F4=10,34,IF(F4=12,42,IF(F4=15,64,IF(F4=18,124,IF(F4=24,267,IF(F4=30,416,IF(F4=36,520,"")))))))))) -> 27 | W4: =IF(G4=4,21, IF(G4=6,27,IF(G4=8,29,IF(G4=10,34,IF(G4=12,42,IF(G4=15,64,IF(G4=18,124,IF(G4=24,267,IF(G4=30,416,IF(G4=36,520,"")))))))))) | X4: =SUM(T4:W4) -> 85 | Y4: =IF(SUM(COUNTIF(D4:G4,4))>0,SUM(COUNTIF(D4:G4,4))&" X 4""","") | Z4: =IF(SUM(COUNTIF(D4:G4,6))>0,SUM(COUNTIF(D4:G4,6))&" X 6""","") -> 1 X 6" | AA4: =IF(SUM(COUNTIF(D4:G4,8))>0,SUM(COUNTIF(D4:G4,8))&" X 8""","") -> 2 X 8" | AB4: =IF(SUM(COUNTIF(D4:G4,10))>0,SUM(COUNTIF(D4:G4,10))&" X 10""","") | AC4: =IF(SUM(COUNTIF(D4:G4,12))>0,SUM(COUNTIF(D4:G4,12))&" X 12""","") | AD4: =IF(SUM(COUNTIF(D4:G4,15))>0,SUM(COUNTIF(D4:G4,15))&" X 15""","") | AE4: =IF(SUM(COUNTIF(D4:G4,18))>0,SUM(COUNTIF(D4:G4,18))&" X 18""","") | AF4: =IF(SUM(COUNTIF(D4:G4,24))>0,SUM(COUNTIF(D4:G4,24))&" X 24""","") | AG4: =IF(SUM(COUNTIF(D4:G4,30))>0,SUM(COUNTIF(D4:G4,30))&" X 30""","")
A5: YD3 | B5: 1234.7 | C5: 1230.2 | D5: 18 | H5: =IF(C5="","",B5-C5) -> 4.5 | I5: =IF(H5="","",H5+0.5) -> 5 | J5: =IF(H5="","",H5+0.67) -> 5.17 | K5: =IF(H5="","",H5+0.83) -> 5.33 | L5: =IF(H5="","",H5+1.17) -> 5.67 | N5: =IF(A5="","",A5) -> YD3 | O5: =IF(R5="","",_xlfn.XLOOKUP(R5,[2]Sheet2!B:B,[2]Sheet2!C:C)) -> 12" Drain Basin W/ Slotted H10 Grate, 0'-5' | P5: =_xlfn.TEXTJOIN(", ", TRUE, IF(Y5<>"", Y5, ""), IF(Z5<>"", Z5, ""), IF(AA5<>"", AA5, ""),IF(AB5<>"",AB5,""), IF(AC5<>"", AC5, ""),IF(AD5<>"", AD5, ""),IF(AE5<>"", AE5, ""),IF(AF5<>"", AF5, ""),IF(AG5<>"", AG5, "")) -> 1 X 18" | R5: DB1205PS | S5: =IF(Sheet2!O5="","",--LEFT(Sheet2!O5,FIND("""",Sheet2!O5)-1)) -> 12 | T5: =IF(D5=4,21, IF(D5=6,27,IF(D5=8,29,IF(D5=10,34,IF(D5=12,42,IF(D5=15,64,IF(D5=18,124,IF(D5=24,267,IF(D5=30,416,IF(D5=36,520,"")))))))))) -> 124 | U5: =IF(E5=4,21, IF(E5=6,27,IF(E5=8,29,IF(E5=10,34,IF(E5=12,42,IF(E5=15,64,IF(E5=18,124,IF(E5=24,267,IF(E5=30,416,IF(E5=36,520,"")))))))))) | V5: =IF(F5=4,21, IF(F5=6,27,IF(F5=8,29,IF(F5=10,34,IF(F5=12,42,IF(F5=15,64,IF(F5=18,124,IF(F5=24,267,IF(F5=30,416,IF(F5=36,520,"")))))))))) | W5: =IF(G5=4,21, IF(G5=6,27,IF(G5=8,29,IF(G5=10,34,IF(G5=12,42,IF(G5=15,64,IF(G5=18,124,IF(G5=24,267,IF(G5=30,416,IF(G5=36,520,"")))))))))) | X5: =SUM(T5:W5) -> 124 | Y5: =IF(SUM(COUNTIF(D5:G5,4))>0,SUM(COUNTIF(D5:G5,4))&" X 4""","") | Z5: =IF(SUM(COUNTIF(D5:G5,6))>0,SUM(COUNTIF(D5:G5,6))&" X 6""","") | AA5: =IF(SUM(COUNTIF(D5:G5,8))>0,SUM(COUNTIF(D5:G5,8))&" X 8""","") | AB5: =IF(SUM(COUNTIF(D5:G5,10))>0,SUM(COUNTIF(D5:G5,10))&" X 10""","") | AC5: =IF(SUM(COUNTIF(D5:G5,12))>0,SUM(COUNTIF(D5:G5,12))&" X 12""","") | AD5: =IF(SUM(COUNTIF(D5:G5,15))>0,SUM(COUNTIF(D5:G5,15))&" X 15""","") | AE5: =IF(SUM(COUNTIF(D5:G5,18))>0,SUM(COUNTIF(D5:G5,18))&" X 18""","") -> 1 X 18" | AF5: =IF(SUM(COUNTIF(D5:G5,24))>0,SUM(COUNTIF(D5:G5,24))&" X 24""","") | AG5: =IF(SUM(COUNTIF(D5:G5,30))>0,SUM(COUNTIF(D5:G5,30))&" X 30""","")
A6: YD6 | B6: 1231.31 | C6: 1227.7 | D6: 15 | E6: 8 | H6: =IF(C6="","",B6-C6) -> 3.61 | I6: =IF(H6="","",H6+0.5) -> 4.11 | J6: =IF(H6="","",H6+0.67) -> 4.28 | K6: =IF(H6="","",H6+0.83) -> 4.44 | L6: =IF(H6="","",H6+1.17) -> 4.78 | N6: =IF(A6="","",A6) -> YD6 | O6: =IF(R6="","",_xlfn.XLOOKUP(R6,[2]Sheet2!B:B,[2]Sheet2!C:C)) -> 24" Drain Basin W/H-10 Domed Grate, 5' - 10' | P6: =_xlfn.TEXTJOIN(", ", TRUE, IF(Y6<>"", Y6, ""), IF(Z6<>"", Z6, ""), IF(AA6<>"", AA6, ""),IF(AB6<>"",AB6,""), IF(AC6<>"", AC6, ""),IF(AD6<>"", AD6, ""),IF(AE6<>"", AE6, ""),IF(AF6<>"", AF6, ""),IF(AG6<>"", AG6, "")) -> 1 X 8", 1 X 15" | R6: DB2410DG | S6: =IF(Sheet2!O6="","",--LEFT(Sheet2!O6,FIND("""",Sheet2!O6)-1)) -> 24 | T6: =IF(D6=4,21, IF(D6=6,27,IF(D6=8,29,IF(D6=10,34,IF(D6=12,42,IF(D6=15,64,IF(D6=18,124,IF(D6=24,267,IF(D6=30,416,IF(D6=36,520,"")))))))))) -> 64 | U6: =IF(E6=4,21, IF(E6=6,27,IF(E6=8,29,IF(E6=10,34,IF(E6=12,42,IF(E6=15,64,IF(E6=18,124,IF(E6=24,267,IF(E6=30,416,IF(E6=36,520,"")))))))))) -> 29 | V6: =IF(F6=4,21, IF(F6=6,27,IF(F6=8,29,IF(F6=10,34,IF(F6=12,42,IF(F6=15,64,IF(F6=18,124,IF(F6=24,267,IF(F6=30,416,IF(F6=36,520,"")))))))))) | W6: =IF(G6=4,21, IF(G6=6,27,IF(G6=8,29,IF(G6=10,34,IF(G6=12,42,IF(G6=15,64,IF(G6=18,124,IF(G6=24,267,IF(G6=30,416,IF(G6=36,520,"")))))))))) | X6: =SUM(T6:W6) -> 93 | Y6: =IF(SUM(COUNTIF(D6:G6,4))>0,SUM(COUNTIF(D6:G6,4))&" X 4""","") | Z6: =IF(SUM(COUNTIF(D6:G6,6))>0,SUM(COUNTIF(D6:G6,6))&" X 6""","") | AA6: =IF(SUM(COUNTIF(D6:G6,8))>0,SUM(COUNTIF(D6:G6,8))&" X 8""","") -> 1 X 8" | AB6: =IF(SUM(COUNTIF(D6:G6,10))>0,SUM(COUNTIF(D6:G6,10))&" X 10""","") | AC6: =IF(SUM(COUNTIF(D6:G6,12))>0,SUM(COUNTIF(D6:G6,12))&" X 12""","") | AD6: =IF(SUM(COUNTIF(D6:G6,15))>0,SUM(COUNTIF(D6:G6,15))&" X 15""","") -> 1 X 15" | AE6: =IF(SUM(COUNTIF(D6:G6,18))>0,SUM(COUNTIF(D6:G6,18))&" X 18""","") | AF6: =IF(SUM(COUNTIF(D6:G6,24))>0,SUM(COUNTIF(D6:G6,24))&" X 24""","") | AG6: =IF(SUM(COUNTIF(D6:G6,30))>0,SUM(COUNTIF(D6:G6,30))&" X 30""","")
A7: YD7 | B7: 1230.59 | C7: 1226.3 | D7: 18 | H7: =IF(C7="","",B7-C7) -> 4.29 | I7: =IF(H7="","",H7+0.5) -> 4.79 | J7: =IF(H7="","",H7+0.67) -> 4.96 | K7: =IF(H7="","",H7+0.83) -> 5.12 | L7: =IF(H7="","",H7+1.17) -> 5.46 | N7: =IF(A7="","",A7) -> YD7 | O7: =IF(R7="","",_xlfn.XLOOKUP(R7,[2]Sheet2!B:B,[2]Sheet2!C:C)) -> 30" X <5' DRAIN BASIN C/W STANDARD SLOT FG | P7: =_xlfn.TEXTJOIN(", ", TRUE, IF(Y7<>"", Y7, ""), IF(Z7<>"", Z7, ""), IF(AA7<>"", AA7, ""),IF(AB7<>"",AB7,""), IF(AC7<>"", AC7, ""),IF(AD7<>"", AD7, ""),IF(AE7<>"", AE7, ""),IF(AF7<>"", AF7, ""),IF(AG7<>"", AG7, "")) -> 1 X 18" | R7: DB3005SS | S7: =IF(Sheet2!O7="","",--LEFT(Sheet2!O7,FIND("""",Sheet2!O7)-1)) -> 30 | T7: =IF(D7=4,21, IF(D7=6,27,IF(D7=8,29,IF(D7=10,34,IF(D7=12,42,IF(D7=15,64,IF(D7=18,124,IF(D7=24,267,IF(D7=30,416,IF(D7=36,520,"")))))))))) -> 124 | U7: =IF(E7=4,21, IF(E7=6,27,IF(E7=8,29,IF(E7=10,34,IF(E7=12,42,IF(E7=15,64,IF(E7=18,124,IF(E7=24,267,IF(E7=30,416,IF(E7=36,520,"")))))))))) | V7: =IF(F7=4,21, IF(F7=6,27,IF(F7=8,29,IF(F7=10,34,IF(F7=12,42,IF(F7=15,64,IF(F7=18,124,IF(F7=24,267,IF(F7=30,416,IF(F7=36,520,"")))))))))) | W7: =IF(G7=4,21, IF(G7=6,27,IF(G7=8,29,IF(G7=10,34,IF(G7=12,42,IF(G7=15,64,IF(G7=18,124,IF(G7=24,267,IF(G7=30,416,IF(G7=36,520,"")))))))))) | X7: =SUM(T7:W7) -> 124 | Y7: =IF(SUM(COUNTIF(D7:G7,4))>0,SUM(COUNTIF(D7:G7,4))&" X 4""","") | Z7: =IF(SUM(COUNTIF(D7:G7,6))>0,SUM(COUNTIF(D7:G7,6))&" X 6""","") | AA7: =IF(SUM(COUNTIF(D7:G7,8))>0,SUM(COUNTIF(D7:G7,8))&" X 8""","") | AB7: =IF(SUM(COUNTIF(D7:G7,10))>0,SUM(COUNTIF(D7:G7,10))&" X 10""","") | AC7: =IF(SUM(COUNTIF(D7:G7,12))>0,SUM(COUNTIF(D7:G7,12))&" X 12""","") | AD7: =IF(SUM(COUNTIF(D7:G7,15))>0,SUM(COUNTIF(D7:G7,15))&" X 15""","") | AE7: =IF(SUM(COUNTIF(D7:G7,18))>0,SUM(COUNTIF(D7:G7,18))&" X 18""","") -> 1 X 18" | AF7: =IF(SUM(COUNTIF(D7:G7,24))>0,SUM(COUNTIF(D7:G7,24))&" X 24""","") | AG7: =IF(SUM(COUNTIF(D7:G7,30))>0,SUM(COUNTIF(D7:G7,30))&" X 30""","")
H8: =IF(C8="","",B8-C8) | I8: =IF(H8="","",H8+0.5) | J8: =IF(H8="","",H8+0.67) | K8: =IF(H8="","",H8+0.83) | L8: =IF(H8="","",H8+1.17) | N8: =IF(A8="","",A8) | O8: =IF(R8="","",_xlfn.XLOOKUP(R8,[2]Sheet2!B:B,[2]Sheet2!C:C)) | P8: =_xlfn.TEXTJOIN(", ", TRUE, IF(Y8<>"", Y8, ""), IF(Z8<>"", Z8, ""), IF(AA8<>"", AA8, ""),IF(AB8<>"",AB8,""), IF(AC8<>"", AC8, ""),IF(AD8<>"", AD8, ""),IF(AE8<>"", AE8, ""),IF(AF8<>"", AF8, ""),IF(AG8<>"", AG8, "")) | S8: =IF(Sheet2!O8="","",--LEFT(Sheet2!O8,FIND("""",Sheet2!O8)-1)) | T8: =IF(D8=4,21, IF(D8=6,27,IF(D8=8,29,IF(D8=10,34,IF(D8=12,42,IF(D8=15,64,IF(D8=18,124,IF(D8=24,267,IF(D8=30,416,IF(D8=36,520,"")))))))))) | U8: =IF(E8=4,21, IF(E8=6,27,IF(E8=8,29,IF(E8=10,34,IF(E8=12,42,IF(E8=15,64,IF(E8=18,124,IF(E8=24,267,IF(E8=30,416,IF(E8=36,520,"")))))))))) | V8: =IF(F8=4,21, IF(F8=6,27,IF(F8=8,29,IF(F8=10,34,IF(F8=12,42,IF(F8=15,64,IF(F8=18,124,IF(F8=24,267,IF(F8=30,416,IF(F8=36,520,"")))))))))) | W8: =IF(G8=4,21, IF(G8=6,27,IF(G8=8,29,IF(G8=10,34,IF(G8=12,42,IF(G8=15,64,IF(G8=18,124,IF(G8=24,267,IF(G8=30,416,IF(G8=36,520,"")))))))))) | X8: =SUM(T8:W8) -> 0 | Y8: =IF(SUM(COUNTIF(D8:G8,4))>0,SUM(COUNTIF(D8:G8,4))&" X 4""","") | Z8: =IF(SUM(COUNTIF(D8:G8,6))>0,SUM(COUNTIF(D8:G8,6))&" X 6""","") | AA8: =IF(SUM(COUNTIF(D8:G8,8))>0,SUM(COUNTIF(D8:G8,8))&" X 8""","") | AB8: =IF(SUM(COUNTIF(D8:G8,10))>0,SUM(COUNTIF(D8:G8,10))&" X 10""","") | AC8: =IF(SUM(COUNTIF(D8:G8,12))>0,SUM(COUNTIF(D8:G8,12))&" X 12""","") | AD8: =IF(SUM(COUNTIF(D8:G8,15))>0,SUM(COUNTIF(D8:G8,15))&" X 15""","") | AE8: =IF(SUM(COUNTIF(D8:G8,18))>0,SUM(COUNTIF(D8:G8,18))&" X 18""","") | AF8: =IF(SUM(COUNTIF(D8:G8,24))>0,SUM(COUNTIF(D8:G8,24))&" X 24""","") | AG8: =IF(SUM(COUNTIF(D8:G8,30))>0,SUM(COUNTIF(D8:G8,30))&" X 30""","")
H9: =IF(C9="","",B9-C9) | I9: =IF(H9="","",H9+0.5) | J9: =IF(H9="","",H9+0.67) | K9: =IF(H9="","",H9+0.83) | L9: =IF(H9="","",H9+1.17) | N9: =IF(A9="","",A9) | O9: =IF(R9="","",_xlfn.XLOOKUP(R9,[2]Sheet2!B:B,[2]Sheet2!C:C)) | P9: =_xlfn.TEXTJOIN(", ", TRUE, IF(Y9<>"", Y9, ""), IF(Z9<>"", Z9, ""), IF(AA9<>"", AA9, ""),IF(AB9<>"",AB9,""), IF(AC9<>"", AC9, ""),IF(AD9<>"", AD9, ""),IF(AE9<>"", AE9, ""),IF(AF9<>"", AF9, ""),IF(AG9<>"", AG9, "")) | S9: =IF(Sheet2!O9="","",--LEFT(Sheet2!O9,FIND("""",Sheet2!O9)-1)) | T9: =IF(D9=4,21, IF(D9=6,27,IF(D9=8,29,IF(D9=10,34,IF(D9=12,42,IF(D9=15,64,IF(D9=18,124,IF(D9=24,267,IF(D9=30,416,IF(D9=36,520,"")))))))))) | U9: =IF(E9=4,21, IF(E9=6,27,IF(E9=8,29,IF(E9=10,34,IF(E9=12,42,IF(E9=15,64,IF(E9=18,124,IF(E9=24,267,IF(E9=30,416,IF(E9=36,520,"")))))))))) | V9: =IF(F9=4,21, IF(F9=6,27,IF(F9=8,29,IF(F9=10,34,IF(F9=12,42,IF(F9=15,64,IF(F9=18,124,IF(F9=24,267,IF(F9=30,416,IF(F9=36,520,"")))))))))) | W9: =IF(G9=4,21, IF(G9=6,27,IF(G9=8,29,IF(G9=10,34,IF(G9=12,42,IF(G9=15,64,IF(G9=18,124,IF(G9=24,267,IF(G9=30,416,IF(G9=36,520,"")))))))))) | X9: =SUM(T9:W9) -> 0 | Y9: =IF(SUM(COUNTIF(D9:G9,4))>0,SUM(COUNTIF(D9:G9,4))&" X 4""","") | Z9: =IF(SUM(COUNTIF(D9:G9,6))>0,SUM(COUNTIF(D9:G9,6))&" X 6""","") | AA9: =IF(SUM(COUNTIF(D9:G9,8))>0,SUM(COUNTIF(D9:G9,8))&" X 8""","") | AB9: =IF(SUM(COUNTIF(D9:G9,10))>0,SUM(COUNTIF(D9:G9,10))&" X 10""","") | AC9: =IF(SUM(COUNTIF(D9:G9,12))>0,SUM(COUNTIF(D9:G9,12))&" X 12""","") | AD9: =IF(SUM(COUNTIF(D9:G9,15))>0,SUM(COUNTIF(D9:G9,15))&" X 15""","") | AE9: =IF(SUM(COUNTIF(D9:G9,18))>0,SUM(COUNTIF(D9:G9,18))&" X 18""","") | AF9: =IF(SUM(COUNTIF(D9:G9,24))>0,SUM(COUNTIF(D9:G9,24))&" X 24""","") | AG9: =IF(SUM(COUNTIF(D9:G9,30))>0,SUM(COUNTIF(D9:G9,30))&" X 30""","")
H10: =IF(C10="","",B10-C10) | I10: =IF(H10="","",H10+0.5) | J10: =IF(H10="","",H10+0.67) | K10: =IF(H10="","",H10+0.83) | L10: =IF(H10="","",H10+1.17) | N10: =IF(A10="","",A10) | O10: =IF(R10="","",_xlfn.XLOOKUP(R10,[2]Sheet2!B:B,[2]Sheet2!C:C)) | P10: =_xlfn.TEXTJOIN(", ", TRUE, IF(Y10<>"", Y10, ""), IF(Z10<>"", Z10, ""), IF(AA10<>"", AA10, ""),IF(AB10<>"",AB10,""), IF(AC10<>"", AC10, ""),IF(AD10<>"", AD10, ""),IF(AE10<>"", AE10, ""),IF(AF10<>"", AF10, ""),IF(AG10<>"", AG10, "")) | S10: =IF(Sheet2!O10="","",--LEFT(Sheet2!O10,FIND("""",Sheet2!O10)-1)) | T10: =IF(D10=4,21, IF(D10=6,27,IF(D10=8,29,IF(D10=10,34,IF(D10=12,42,IF(D10=15,64,IF(D10=18,124,IF(D10=24,267,IF(D10=30,416,IF(D10=36,520,"")))))))))) | U10: =IF(E10=4,21, IF(E10=6,27,IF(E10=8,29,IF(E10=10,34,IF(E10=12,42,IF(E10=15,64,IF(E10=18,124,IF(E10=24,267,IF(E10=30,416,IF(E10=36,520,"")))))))))) | V10: =IF(F10=4,21, IF(F10=6,27,IF(F10=8,29,IF(F10=10,34,IF(F10=12,42,IF(F10=15,64,IF(F10=18,124,IF(F10=24,267,IF(F10=30,416,IF(F10=36,520,"")))))))))) | W10: =IF(G10=4,21, IF(G10=6,27,IF(G10=8,29,IF(G10=10,34,IF(G10=12,42,IF(G10=15,64,IF(G10=18,124,IF(G10=24,267,IF(G10=30,416,IF(G10=36,520,"")))))))))) | X10: =SUM(T10:W10) -> 0 | Y10: =IF(SUM(COUNTIF(D10:G10,4))>0,SUM(COUNTIF(D10:G10,4))&" X 4""","") | Z10: =IF(SUM(COUNTIF(D10:G10,6))>0,SUM(COUNTIF(D10:G10,6))&" X 6""","") | AA10: =IF(SUM(COUNTIF(D10:G10,8))>0,SUM(COUNTIF(D10:G10,8))&" X 8""","") | AB10: =IF(SUM(COUNTIF(D10:G10,10))>0,SUM(COUNTIF(D10:G10,10))&" X 10""","") | AC10: =IF(SUM(COUNTIF(D10:G10,12))>0,SUM(COUNTIF(D10:G10,12))&" X 12""","") | AD10: =IF(SUM(COUNTIF(D10:G10,15))>0,SUM(COUNTIF(D10:G10,15))&" X 15""","") | AE10: =IF(SUM(COUNTIF(D10:G10,18))>0,SUM(COUNTIF(D10:G10,18))&" X 18""","") | AF10: =IF(SUM(COUNTIF(D10:G10,24))>0,SUM(COUNTIF(D10:G10,24))&" X 24""","") | AG10: =IF(SUM(COUNTIF(D10:G10,30))>0,SUM(COUNTIF(D10:G10,30))&" X 30""","")
H11: =IF(C11="","",B11-C11) | I11: =IF(H11="","",H11+0.5) | J11: =IF(H11="","",H11+0.67) | K11: =IF(H11="","",H11+0.83) | L11: =IF(H11="","",H11+1.17) | N11: =IF(A11="","",A11) | O11: =IF(R11="","",_xlfn.XLOOKUP(R11,[2]Sheet2!B:B,[2]Sheet2!C:C)) | P11: =_xlfn.TEXTJOIN(", ", TRUE, IF(Y11<>"", Y11, ""), IF(Z11<>"", Z11, ""), IF(AA11<>"", AA11, ""),IF(AB11<>"",AB11,""), IF(AC11<>"", AC11, ""),IF(AD11<>"", AD11, ""),IF(AE11<>"", AE11, ""),IF(AF11<>"", AF11, ""),IF(AG11<>"", AG11, "")) | S11: =IF(Sheet2!O11="","",--LEFT(Sheet2!O11,FIND("""",Sheet2!O11)-1)) | T11: =IF(D11=4,21, IF(D11=6,27,IF(D11=8,29,IF(D11=10,34,IF(D11=12,42,IF(D11=15,64,IF(D11=18,124,IF(D11=24,267,IF(D11=30,416,IF(D11=36,520,"")))))))))) | U11: =IF(E11=4,21, IF(E11=6,27,IF(E11=8,29,IF(E11=10,34,IF(E11=12,42,IF(E11=15,64,IF(E11=18,124,IF(E11=24,267,IF(E11=30,416,IF(E11=36,520,"")))))))))) | V11: =IF(F11=4,21, IF(F11=6,27,IF(F11=8,29,IF(F11=10,34,IF(F11=12,42,IF(F11=15,64,IF(F11=18,124,IF(F11=24,267,IF(F11=30,416,IF(F11=36,520,"")))))))))) | W11: =IF(G11=4,21, IF(G11=6,27,IF(G11=8,29,IF(G11=10,34,IF(G11=12,42,IF(G11=15,64,IF(G11=18,124,IF(G11=24,267,IF(G11=30,416,IF(G11=36,520,"")))))))))) | X11: =SUM(T11:W11) -> 0 | Y11: =IF(SUM(COUNTIF(D11:G11,4))>0,SUM(COUNTIF(D11:G11,4))&" X 4""","") | Z11: =IF(SUM(COUNTIF(D11:G11,6))>0,SUM(COUNTIF(D11:G11,6))&" X 6""","") | AA11: =IF(SUM(COUNTIF(D11:G11,8))>0,SUM(COUNTIF(D11:G11,8))&" X 8""","") | AB11: =IF(SUM(COUNTIF(D11:G11,10))>0,SUM(COUNTIF(D11:G11,10))&" X 10""","") | AC11: =IF(SUM(COUNTIF(D11:G11,12))>0,SUM(COUNTIF(D11:G11,12))&" X 12""","") | AD11: =IF(SUM(COUNTIF(D11:G11,15))>0,SUM(COUNTIF(D11:G11,15))&" X 15""","") | AE11: =IF(SUM(COUNTIF(D11:G11,18))>0,SUM(COUNTIF(D11:G11,18))&" X 18""","") | AF11: =IF(SUM(COUNTIF(D11:G11,24))>0,SUM(COUNTIF(D11:G11,24))&" X 24""","") | AG11: =IF(SUM(COUNTIF(D11:G11,30))>0,SUM(COUNTIF(D11:G11,30))&" X 30""","")
H12: =IF(C12="","",B12-C12) | I12: =IF(H12="","",H12+0.5) | J12: =IF(H12="","",H12+0.67) | K12: =IF(H12="","",H12+0.83) | L12: =IF(H12="","",H12+1.17) | N12: =IF(A12="","",A12) | O12: =IF(R12="","",_xlfn.XLOOKUP(R12,[2]Sheet2!B:B,[2]Sheet2!C:C)) | P12: =_xlfn.TEXTJOIN(", ", TRUE, IF(Y12<>"", Y12, ""), IF(Z12<>"", Z12, ""), IF(AA12<>"", AA12, ""),IF(AB12<>"",AB12,""), IF(AC12<>"", AC12, ""),IF(AD12<>"", AD12, ""),IF(AE12<>"", AE12, ""),IF(AF12<>"", AF12, ""),IF(AG12<>"", AG12, "")) | S12: =IF(Sheet2!O12="","",--LEFT(Sheet2!O12,FIND("""",Sheet2!O12)-1)) | T12: =IF(D12=4,21, IF(D12=6,27,IF(D12=8,29,IF(D12=10,34,IF(D12=12,42,IF(D12=15,64,IF(D12=18,124,IF(D12=24,267,IF(D12=30,416,IF(D12=36,520,"")))))))))) | U12: =IF(E12=4,21, IF(E12=6,27,IF(E12=8,29,IF(E12=10,34,IF(E12=12,42,IF(E12=15,64,IF(E12=18,124,IF(E12=24,267,IF(E12=30,416,IF(E12=36,520,"")))))))))) | V12: =IF(F12=4,21, IF(F12=6,27,IF(F12=8,29,IF(F12=10,34,IF(F12=12,42,IF(F12=15,64,IF(F12=18,124,IF(F12=24,267,IF(F12=30,416,IF(F12=36,520,"")))))))))) | W12: =IF(G12=4,21, IF(G12=6,27,IF(G12=8,29,IF(G12=10,34,IF(G12=12,42,IF(G12=15,64,IF(G12=18,124,IF(G12=24,267,IF(G12=30,416,IF(G12=36,520,"")))))))))) | X12: =SUM(T12:W12) -> 0 | Y12: =IF(SUM(COUNTIF(D12:G12,4))>0,SUM(COUNTIF(D12:G12,4))&" X 4""","") | Z12: =IF(SUM(COUNTIF(D12:G12,6))>0,SUM(COUNTIF(D12:G12,6))&" X 6""","") | AA12: =IF(SUM(COUNTIF(D12:G12,8))>0,SUM(COUNTIF(D12:G12,8))&" X 8""","") | AB12: =IF(SUM(COUNTIF(D12:G12,10))>0,SUM(COUNTIF(D12:G12,10))&" X 10""","") | AC12: =IF(SUM(COUNTIF(D12:G12,12))>0,SUM(COUNTIF(D12:G12,12))&" X 12""","") | AD12: =IF(SUM(COUNTIF(D12:G12,15))>0,SUM(COUNTIF(D12:G12,15))&" X 15""","") | AE12: =IF(SUM(COUNTIF(D12:G12,18))>0,SUM(COUNTIF(D12:G12,18))&" X 18""","") | AF12: =IF(SUM(COUNTIF(D12:G12,24))>0,SUM(COUNTIF(D12:G12,24))&" X 24""","") | AG12: =IF(SUM(COUNTIF(D12:G12,30))>0,SUM(COUNTIF(D12:G12,30))&" X 30""","")
H13: =IF(C13="","",B13-C13) | I13: =IF(H13="","",H13+0.5) | J13: =IF(H13="","",H13+0.67) | K13: =IF(H13="","",H13+0.83) | L13: =IF(H13="","",H13+1.17) | N13: =IF(A13="","",A13) | O13: =IF(R13="","",_xlfn.XLOOKUP(R13,[2]Sheet2!B:B,[2]Sheet2!C:C)) | P13: =_xlfn.TEXTJOIN(", ", TRUE, IF(Y13<>"", Y13, ""), IF(Z13<>"", Z13, ""), IF(AA13<>"", AA13, ""),IF(AB13<>"",AB13,""), IF(AC13<>"", AC13, ""),IF(AD13<>"", AD13, ""),IF(AE13<>"", AE13, ""),IF(AF13<>"", AF13, ""),IF(AG13<>"", AG13, "")) | S13: =IF(Sheet2!O13="","",--LEFT(Sheet2!O13,FIND("""",Sheet2!O13)-1)) | T13: =IF(D13=4,21, IF(D13=6,27,IF(D13=8,29,IF(D13=10,34,IF(D13=12,42,IF(D13=15,64,IF(D13=18,124,IF(D13=24,267,IF(D13=30,416,IF(D13=36,520,"")))))))))) | U13: =IF(E13=4,21, IF(E13=6,27,IF(E13=8,29,IF(E13=10,34,IF(E13=12,42,IF(E13=15,64,IF(E13=18,124,IF(E13=24,267,IF(E13=30,416,IF(E13=36,520,"")))))))))) | V13: =IF(F13=4,21, IF(F13=6,27,IF(F13=8,29,IF(F13=10,34,IF(F13=12,42,IF(F13=15,64,IF(F13=18,124,IF(F13=24,267,IF(F13=30,416,IF(F13=36,520,"")))))))))) | W13: =IF(G13=4,21, IF(G13=6,27,IF(G13=8,29,IF(G13=10,34,IF(G13=12,42,IF(G13=15,64,IF(G13=18,124,IF(G13=24,267,IF(G13=30,416,IF(G13=36,520,"")))))))))) | X13: =SUM(T13:W13) -> 0 | Y13: =IF(SUM(COUNTIF(D13:G13,4))>0,SUM(COUNTIF(D13:G13,4))&" X 4""","") | Z13: =IF(SUM(COUNTIF(D13:G13,6))>0,SUM(COUNTIF(D13:G13,6))&" X 6""","") | AA13: =IF(SUM(COUNTIF(D13:G13,8))>0,SUM(COUNTIF(D13:G13,8))&" X 8""","") | AB13: =IF(SUM(COUNTIF(D13:G13,10))>0,SUM(COUNTIF(D13:G13,10))&" X 10""","") | AC13: =IF(SUM(COUNTIF(D13:G13,12))>0,SUM(COUNTIF(D13:G13,12))&" X 12""","") | AD13: =IF(SUM(COUNTIF(D13:G13,15))>0,SUM(COUNTIF(D13:G13,15))&" X 15""","") | AE13: =IF(SUM(COUNTIF(D13:G13,18))>0,SUM(COUNTIF(D13:G13,18))&" X 18""","") | AF13: =IF(SUM(COUNTIF(D13:G13,24))>0,SUM(COUNTIF(D13:G13,24))&" X 24""","") | AG13: =IF(SUM(COUNTIF(D13:G13,30))>0,SUM(COUNTIF(D13:G13,30))&" X 30""","")
H14: =IF(C14="","",B14-C14) | I14: =IF(H14="","",H14+0.5) | J14: =IF(H14="","",H14+0.67) | K14: =IF(H14="","",H14+0.83) | L14: =IF(H14="","",H14+1.17) | N14: =IF(A14="","",A14) | O14: =IF(R14="","",_xlfn.XLOOKUP(R14,[2]Sheet2!B:B,[2]Sheet2!C:C)) | P14: =_xlfn.TEXTJOIN(", ", TRUE, IF(Y14<>"", Y14, ""), IF(Z14<>"", Z14, ""), IF(AA14<>"", AA14, ""),IF(AB14<>"",AB14,""), IF(AC14<>"", AC14, ""),IF(AD14<>"", AD14, ""),IF(AE14<>"", AE14, ""),IF(AF14<>"", AF14, ""),IF(AG14<>"", AG14, "")) | S14: =IF(Sheet2!O14="","",--LEFT(Sheet2!O14,FIND("""",Sheet2!O14)-1)) | T14: =IF(D14=4,21, IF(D14=6,27,IF(D14=8,29,IF(D14=10,34,IF(D14=12,42,IF(D14=15,64,IF(D14=18,124,IF(D14=24,267,IF(D14=30,416,IF(D14=36,520,"")))))))))) | U14: =IF(E14=4,21, IF(E14=6,27,IF(E14=8,29,IF(E14=10,34,IF(E14=12,42,IF(E14=15,64,IF(E14=18,124,IF(E14=24,267,IF(E14=30,416,IF(E14=36,520,"")))))))))) | V14: =IF(F14=4,21, IF(F14=6,27,IF(F14=8,29,IF(F14=10,34,IF(F14=12,42,IF(F14=15,64,IF(F14=18,124,IF(F14=24,267,IF(F14=30,416,IF(F14=36,520,"")))))))))) | W14: =IF(G14=4,21, IF(G14=6,27,IF(G14=8,29,IF(G14=10,34,IF(G14=12,42,IF(G14=15,64,IF(G14=18,124,IF(G14=24,267,IF(G14=30,416,IF(G14=36,520,"")))))))))) | X14: =SUM(T14:W14) -> 0 | Y14: =IF(SUM(COUNTIF(D14:G14,4))>0,SUM(COUNTIF(D14:G14,4))&" X 4""","") | Z14: =IF(SUM(COUNTIF(D14:G14,6))>0,SUM(COUNTIF(D14:G14,6))&" X 6""","") | AA14: =IF(SUM(COUNTIF(D14:G14,8))>0,SUM(COUNTIF(D14:G14,8))&" X 8""","") | AB14: =IF(SUM(COUNTIF(D14:G14,10))>0,SUM(COUNTIF(D14:G14,10))&" X 10""","") | AC14: =IF(SUM(COUNTIF(D14:G14,12))>0,SUM(COUNTIF(D14:G14,12))&" X 12""","") | AD14: =IF(SUM(COUNTIF(D14:G14,15))>0,SUM(COUNTIF(D14:G14,15))&" X 15""","") | AE14: =IF(SUM(COUNTIF(D14:G14,18))>0,SUM(COUNTIF(D14:G14,18))&" X 18""","") | AF14: =IF(SUM(COUNTIF(D14:G14,24))>0,SUM(COUNTIF(D14:G14,24))&" X 24""","") | AG14: =IF(SUM(COUNTIF(D14:G14,30))>0,SUM(COUNTIF(D14:G14,30))&" X 30""","")
H15: =IF(C15="","",B15-C15) | I15: =IF(H15="","",H15+0.5) | J15: =IF(H15="","",H15+0.67) | K15: =IF(H15="","",H15+0.83) | L15: =IF(H15="","",H15+1.17) | N15: =IF(A15="","",A15) | O15: =IF(R15="","",_xlfn.XLOOKUP(R15,[2]Sheet2!B:B,[2]Sheet2!C:C)) | P15: =_xlfn.TEXTJOIN(", ", TRUE, IF(Y15<>"", Y15, ""), IF(Z15<>"", Z15, ""), IF(AA15<>"", AA15, ""),IF(AB15<>"",AB15,""), IF(AC15<>"", AC15, ""),IF(AD15<>"", AD15, ""),IF(AE15<>"", AE15, ""),IF(AF15<>"", AF15, ""),IF(AG15<>"", AG15, "")) | S15: =IF(Sheet2!O15="","",--LEFT(Sheet2!O15,FIND("""",Sheet2!O15)-1)) | T15: =IF(D15=4,21, IF(D15=6,27,IF(D15=8,29,IF(D15=10,34,IF(D15=12,42,IF(D15=15,64,IF(D15=18,124,IF(D15=24,267,IF(D15=30,416,IF(D15=36,520,"")))))))))) | U15: =IF(E15=4,21, IF(E15=6,27,IF(E15=8,29,IF(E15=10,34,IF(E15=12,42,IF(E15=15,64,IF(E15=18,124,IF(E15=24,267,IF(E15=30,416,IF(E15=36,520,"")))))))))) | V15: =IF(F15=4,21, IF(F15=6,27,IF(F15=8,29,IF(F15=10,34,IF(F15=12,42,IF(F15=15,64,IF(F15=18,124,IF(F15=24,267,IF(F15=30,416,IF(F15=36,520,"")))))))))) | W15: =IF(G15=4,21, IF(G15=6,27,IF(G15=8,29,IF(G15=10,34,IF(G15=12,42,IF(G15=15,64,IF(G15=18,124,IF(G15=24,267,IF(G15=30,416,IF(G15=36,520,"")))))))))) | X15: =SUM(T15:W15) -> 0 | Y15: =IF(SUM(COUNTIF(D15:G15,4))>0,SUM(COUNTIF(D15:G15,4))&" X 4""","") | Z15: =IF(SUM(COUNTIF(D15:G15,6))>0,SUM(COUNTIF(D15:G15,6))&" X 6""","") | AA15: =IF(SUM(COUNTIF(D15:G15,8))>0,SUM(COUNTIF(D15:G15,8))&" X 8""","") | AB15: =IF(SUM(COUNTIF(D15:G15,10))>0,SUM(COUNTIF(D15:G15,10))&" X 10""","") | AC15: =IF(SUM(COUNTIF(D15:G15,12))>0,SUM(COUNTIF(D15:G15,12))&" X 12""","") | AD15: =IF(SUM(COUNTIF(D15:G15,15))>0,SUM(COUNTIF(D15:G15,15))&" X 15""","") | AE15: =IF(SUM(COUNTIF(D15:G15,18))>0,SUM(COUNTIF(D15:G15,18))&" X 18""","") | AF15: =IF(SUM(COUNTIF(D15:G15,24))>0,SUM(COUNTIF(D15:G15,24))&" X 24""","") | AG15: =IF(SUM(COUNTIF(D15:G15,30))>0,SUM(COUNTIF(D15:G15,30))&" X 30""","")
H16: =IF(C16="","",B16-C16) | I16: =IF(H16="","",H16+0.5) | J16: =IF(H16="","",H16+0.67) | K16: =IF(H16="","",H16+0.83) | L16: =IF(H16="","",H16+1.17) | N16: =IF(A16="","",A16) | O16: =IF(R16="","",_xlfn.XLOOKUP(R16,[2]Sheet2!B:B,[2]Sheet2!C:C)) | P16: =_xlfn.TEXTJOIN(", ", TRUE, IF(Y16<>"", Y16, ""), IF(Z16<>"", Z16, ""), IF(AA16<>"", AA16, ""),IF(AB16<>"",AB16,""), IF(AC16<>"", AC16, ""),IF(AD16<>"", AD16, ""),IF(AE16<>"", AE16, ""),IF(AF16<>"", AF16, ""),IF(AG16<>"", AG16, "")) | S16: =IF(Sheet2!O16="","",--LEFT(Sheet2!O16,FIND("""",Sheet2!O16)-1)) | T16: =IF(D16=4,21, IF(D16=6,27,IF(D16=8,29,IF(D16=10,34,IF(D16=12,42,IF(D16=15,64,IF(D16=18,124,IF(D16=24,267,IF(D16=30,416,IF(D16=36,520,"")))))))))) | U16: =IF(E16=4,21, IF(E16=6,27,IF(E16=8,29,IF(E16=10,34,IF(E16=12,42,IF(E16=15,64,IF(E16=18,124,IF(E16=24,267,IF(E16=30,416,IF(E16=36,520,"")))))))))) | V16: =IF(F16=4,21, IF(F16=6,27,IF(F16=8,29,IF(F16=10,34,IF(F16=12,42,IF(F16=15,64,IF(F16=18,124,IF(F16=24,267,IF(F16=30,416,IF(F16=36,520,"")))))))))) | W16: =IF(G16=4,21, IF(G16=6,27,IF(G16=8,29,IF(G16=10,34,IF(G16=12,42,IF(G16=15,64,IF(G16=18,124,IF(G16=24,267,IF(G16=30,416,IF(G16=36,520,"")))))))))) | X16: =SUM(T16:W16) -> 0 | Y16: =IF(SUM(COUNTIF(D16:G16,4))>0,SUM(COUNTIF(D16:G16,4))&" X 4""","") | Z16: =IF(SUM(COUNTIF(D16:G16,6))>0,SUM(COUNTIF(D16:G16,6))&" X 6""","") | AA16: =IF(SUM(COUNTIF(D16:G16,8))>0,SUM(COUNTIF(D16:G16,8))&" X 8""","") | AB16: =IF(SUM(COUNTIF(D16:G16,10))>0,SUM(COUNTIF(D16:G16,10))&" X 10""","") | AC16: =IF(SUM(COUNTIF(D16:G16,12))>0,SUM(COUNTIF(D16:G16,12))&" X 12""","") | AD16: =IF(SUM(COUNTIF(D16:G16,15))>0,SUM(COUNTIF(D16:G16,15))&" X 15""","") | AE16: =IF(SUM(COUNTIF(D16:G16,18))>0,SUM(COUNTIF(D16:G16,18))&" X 18""","") | AF16: =IF(SUM(COUNTIF(D16:G16,24))>0,SUM(COUNTIF(D16:G16,24))&" X 24""","") | AG16: =IF(SUM(COUNTIF(D16:G16,30))>0,SUM(COUNTIF(D16:G16,30))&" X 30""","")
H17: =IF(C17="","",B17-C17) | I17: =IF(H17="","",H17+0.5) | J17: =IF(H17="","",H17+0.67) | K17: =IF(H17="","",H17+0.83) | L17: =IF(H17="","",H17+1.17) | N17: =IF(A17="","",A17) | O17: =IF(R17="","",_xlfn.XLOOKUP(R17,[2]Sheet2!B:B,[2]Sheet2!C:C)) | P17: =_xlfn.TEXTJOIN(", ", TRUE, IF(Y17<>"", Y17, ""), IF(Z17<>"", Z17, ""), IF(AA17<>"", AA17, ""),IF(AB17<>"",AB17,""), IF(AC17<>"", AC17, ""),IF(AD17<>"", AD17, ""),IF(AE17<>"", AE17, ""),IF(AF17<>"", AF17, ""),IF(AG17<>"", AG17, "")) | S17: =IF(Sheet2!O17="","",--LEFT(Sheet2!O17,FIND("""",Sheet2!O17)-1)) | T17: =IF(D17=4,21, IF(D17=6,27,IF(D17=8,29,IF(D17=10,34,IF(D17=12,42,IF(D17=15,64,IF(D17=18,124,IF(D17=24,267,IF(D17=30,416,IF(D17=36,520,"")))))))))) | U17: =IF(E17=4,21, IF(E17=6,27,IF(E17=8,29,IF(E17=10,34,IF(E17=12,42,IF(E17=15,64,IF(E17=18,124,IF(E17=24,267,IF(E17=30,416,IF(E17=36,520,"")))))))))) | V17: =IF(F17=4,21, IF(F17=6,27,IF(F17=8,29,IF(F17=10,34,IF(F17=12,42,IF(F17=15,64,IF(F17=18,124,IF(F17=24,267,IF(F17=30,416,IF(F17=36,520,"")))))))))) | W17: =IF(G17=4,21, IF(G17=6,27,IF(G17=8,29,IF(G17=10,34,IF(G17=12,42,IF(G17=15,64,IF(G17=18,124,IF(G17=24,267,IF(G17=30,416,IF(G17=36,520,"")))))))))) | X17: =SUM(T17:W17) -> 0 | Y17: =IF(SUM(COUNTIF(D17:G17,4))>0,SUM(COUNTIF(D17:G17,4))&" X 4""","") | Z17: =IF(SUM(COUNTIF(D17:G17,6))>0,SUM(COUNTIF(D17:G17,6))&" X 6""","") | AA17: =IF(SUM(COUNTIF(D17:G17,8))>0,SUM(COUNTIF(D17:G17,8))&" X 8""","") | AB17: =IF(SUM(COUNTIF(D17:G17,10))>0,SUM(COUNTIF(D17:G17,10))&" X 10""","") | AC17: =IF(SUM(COUNTIF(D17:G17,12))>0,SUM(COUNTIF(D17:G17,12))&" X 12""","") | AD17: =IF(SUM(COUNTIF(D17:G17,15))>0,SUM(COUNTIF(D17:G17,15))&" X 15""","") | AE17: =IF(SUM(COUNTIF(D17:G17,18))>0,SUM(COUNTIF(D17:G17,18))&" X 18""","") | AF17: =IF(SUM(COUNTIF(D17:G17,24))>0,SUM(COUNTIF(D17:G17,24))&" X 24""","") | AG17: =IF(SUM(COUNTIF(D17:G17,30))>0,SUM(COUNTIF(D17:G17,30))&" X 30""","")
H18: =IF(C18="","",B18-C18) | I18: =IF(H18="","",H18+0.5) | J18: =IF(H18="","",H18+0.67) | K18: =IF(H18="","",H18+0.83) | L18: =IF(H18="","",H18+1.17) | N18: =IF(A18="","",A18) | O18: =IF(R18="","",_xlfn.XLOOKUP(R18,[2]Sheet2!B:B,[2]Sheet2!C:C)) | P18: =_xlfn.TEXTJOIN(", ", TRUE, IF(Y18<>"", Y18, ""), IF(Z18<>"", Z18, ""), IF(AA18<>"", AA18, ""),IF(AB18<>"",AB18,""), IF(AC18<>"", AC18, ""),IF(AD18<>"", AD18, ""),IF(AE18<>"", AE18, ""),IF(AF18<>"", AF18, ""),IF(AG18<>"", AG18, "")) | S18: =IF(Sheet2!O18="","",--LEFT(Sheet2!O18,FIND("""",Sheet2!O18)-1)) | T18: =IF(D18=4,21, IF(D18=6,27,IF(D18=8,29,IF(D18=10,34,IF(D18=12,42,IF(D18=15,64,IF(D18=18,124,IF(D18=24,267,IF(D18=30,416,IF(D18=36,520,"")))))))))) | U18: =IF(E18=4,21, IF(E18=6,27,IF(E18=8,29,IF(E18=10,34,IF(E18=12,42,IF(E18=15,64,IF(E18=18,124,IF(E18=24,267,IF(E18=30,416,IF(E18=36,520,"")))))))))) | V18: =IF(F18=4,21, IF(F18=6,27,IF(F18=8,29,IF(F18=10,34,IF(F18=12,42,IF(F18=15,64,IF(F18=18,124,IF(F18=24,267,IF(F18=30,416,IF(F18=36,520,"")))))))))) | W18: =IF(G18=4,21, IF(G18=6,27,IF(G18=8,29,IF(G18=10,34,IF(G18=12,42,IF(G18=15,64,IF(G18=18,124,IF(G18=24,267,IF(G18=30,416,IF(G18=36,520,"")))))))))) | X18: =SUM(T18:W18) -> 0 | Y18: =IF(SUM(COUNTIF(D18:G18,4))>0,SUM(COUNTIF(D18:G18,4))&" X 4""","") | Z18: =IF(SUM(COUNTIF(D18:G18,6))>0,SUM(COUNTIF(D18:G18,6))&" X 6""","") | AA18: =IF(SUM(COUNTIF(D18:G18,8))>0,SUM(COUNTIF(D18:G18,8))&" X 8""","") | AB18: =IF(SUM(COUNTIF(D18:G18,10))>0,SUM(COUNTIF(D18:G18,10))&" X 10""","") | AC18: =IF(SUM(COUNTIF(D18:G18,12))>0,SUM(COUNTIF(D18:G18,12))&" X 12""","") | AD18: =IF(SUM(COUNTIF(D18:G18,15))>0,SUM(COUNTIF(D18:G18,15))&" X 15""","") | AE18: =IF(SUM(COUNTIF(D18:G18,18))>0,SUM(COUNTIF(D18:G18,18))&" X 18""","") | AF18: =IF(SUM(COUNTIF(D18:G18,24))>0,SUM(COUNTIF(D18:G18,24))&" X 24""","") | AG18: =IF(SUM(COUNTIF(D18:G18,30))>0,SUM(COUNTIF(D18:G18,30))&" X 30""","")
H19: =IF(C19="","",B19-C19) | I19: =IF(H19="","",H19+0.5) | J19: =IF(H19="","",H19+0.67) | K19: =IF(H19="","",H19+0.83) | L19: =IF(H19="","",H19+1.17) | N19: =IF(A19="","",A19) | O19: =IF(R19="","",_xlfn.XLOOKUP(R19,[2]Sheet2!B:B,[2]Sheet2!C:C)) | P19: =_xlfn.TEXTJOIN(", ", TRUE, IF(Y19<>"", Y19, ""), IF(Z19<>"", Z19, ""), IF(AA19<>"", AA19, ""),IF(AB19<>"",AB19,""), IF(AC19<>"", AC19, ""),IF(AD19<>"", AD19, ""),IF(AE19<>"", AE19, ""),IF(AF19<>"", AF19, ""),IF(AG19<>"", AG19, "")) | S19: =IF(Sheet2!O19="","",--LEFT(Sheet2!O19,FIND("""",Sheet2!O19)-1)) | T19: =IF(D19=4,21, IF(D19=6,27,IF(D19=8,29,IF(D19=10,34,IF(D19=12,42,IF(D19=15,64,IF(D19=18,124,IF(D19=24,267,IF(D19=30,416,IF(D19=36,520,"")))))))))) | U19: =IF(E19=4,21, IF(E19=6,27,IF(E19=8,29,IF(E19=10,34,IF(E19=12,42,IF(E19=15,64,IF(E19=18,124,IF(E19=24,267,IF(E19=30,416,IF(E19=36,520,"")))))))))) | V19: =IF(F19=4,21, IF(F19=6,27,IF(F19=8,29,IF(F19=10,34,IF(F19=12,42,IF(F19=15,64,IF(F19=18,124,IF(F19=24,267,IF(F19=30,416,IF(F19=36,520,"")))))))))) | W19: =IF(G19=4,21, IF(G19=6,27,IF(G19=8,29,IF(G19=10,34,IF(G19=12,42,IF(G19=15,64,IF(G19=18,124,IF(G19=24,267,IF(G19=30,416,IF(G19=36,520,"")))))))))) | X19: =SUM(T19:W19) -> 0 | Y19: =IF(SUM(COUNTIF(D19:G19,4))>0,SUM(COUNTIF(D19:G19,4))&" X 4""","") | Z19: =IF(SUM(COUNTIF(D19:G19,6))>0,SUM(COUNTIF(D19:G19,6))&" X 6""","") | AA19: =IF(SUM(COUNTIF(D19:G19,8))>0,SUM(COUNTIF(D19:G19,8))&" X 8""","") | AB19: =IF(SUM(COUNTIF(D19:G19,10))>0,SUM(COUNTIF(D19:G19,10))&" X 10""","") | AC19: =IF(SUM(COUNTIF(D19:G19,12))>0,SUM(COUNTIF(D19:G19,12))&" X 12""","") | AD19: =IF(SUM(COUNTIF(D19:G19,15))>0,SUM(COUNTIF(D19:G19,15))&" X 15""","") | AE19: =IF(SUM(COUNTIF(D19:G19,18))>0,SUM(COUNTIF(D19:G19,18))&" X 18""","") | AF19: =IF(SUM(COUNTIF(D19:G19,24))>0,SUM(COUNTIF(D19:G19,24))&" X 24""","") | AG19: =IF(SUM(COUNTIF(D19:G19,30))>0,SUM(COUNTIF(D19:G19,30))&" X 30""","")
